[2024-06-05 19:19:19][WARNING] Not Found: /favicon.ico
[2024-06-05 19:19:37][WARNING] Not Found: /favicon.ico
[2024-06-05 19:27:08][WARNING] Not Found: /favicon.ico
[2024-06-05 19:33:49][WARNING] Not Found: /favicon.ico
[2024-06-05 19:35:11][ERROR] Internal Server Error: /restEndpoint/
Traceback (most recent call last):
  File "/home/schwerti/Documents/GitHub/SAMJ-CSDC26BB/SAMJ-Django-TBC/env/lib/python3.12/site-packages/django/core/handlers/exception.py", line 55, in inner
    response = get_response(request)
               ^^^^^^^^^^^^^^^^^^^^^
  File "/home/schwerti/Documents/GitHub/SAMJ-CSDC26BB/SAMJ-Django-TBC/env/lib/python3.12/site-packages/django/core/handlers/base.py", line 197, in _get_response
    response = wrapped_callback(request, *callback_args, **callback_kwargs)
               ^^^^^^^^^^^^^^^^^^^^^^^^^^^^^^^^^^^^^^^^^^^^^^^^^^^^^^^^^^^^
  File "/home/schwerti/Documents/GitHub/SAMJ-CSDC26BB/SAMJ-Django-TBC/env/lib/python3.12/site-packages/django/views/generic/base.py", line 104, in view
    return self.dispatch(request, *args, **kwargs)
           ^^^^^^^^^^^^^^^^^^^^^^^^^^^^^^^^^^^^^^^
  File "/home/schwerti/Documents/GitHub/SAMJ-CSDC26BB/SAMJ-Django-TBC/env/lib/python3.12/site-packages/django/views/generic/base.py", line 143, in dispatch
    return handler(request, *args, **kwargs)
           ^^^^^^^^^^^^^^^^^^^^^^^^^^^^^^^^^
  File "/home/schwerti/Documents/GitHub/SAMJ-CSDC26BB/SAMJ-Django-TBC/samjTBC/samj/viewClasses/restEndpoint.py", line 9, in get
    logger.info("Forwarding -> " + CallForwardingRecords.objects.all())
                ~~~~~~~~~~~~~~~~~^~~~~~~~~~~~~~~~~~~~~~~~~~~~~~~~~~~~~
TypeError: can only concatenate str (not "QuerySet") to str
[2024-06-05 19:35:11][ERROR] "GET /restEndpoint/ HTTP/1.1" 500 84604
[2024-06-05 19:35:16][ERROR] Internal Server Error: /restEndpoint/
Traceback (most recent call last):
  File "/home/schwerti/Documents/GitHub/SAMJ-CSDC26BB/SAMJ-Django-TBC/env/lib/python3.12/site-packages/django/core/handlers/exception.py", line 55, in inner
    response = get_response(request)
               ^^^^^^^^^^^^^^^^^^^^^
  File "/home/schwerti/Documents/GitHub/SAMJ-CSDC26BB/SAMJ-Django-TBC/env/lib/python3.12/site-packages/django/core/handlers/base.py", line 197, in _get_response
    response = wrapped_callback(request, *callback_args, **callback_kwargs)
               ^^^^^^^^^^^^^^^^^^^^^^^^^^^^^^^^^^^^^^^^^^^^^^^^^^^^^^^^^^^^
  File "/home/schwerti/Documents/GitHub/SAMJ-CSDC26BB/SAMJ-Django-TBC/env/lib/python3.12/site-packages/django/views/generic/base.py", line 104, in view
    return self.dispatch(request, *args, **kwargs)
           ^^^^^^^^^^^^^^^^^^^^^^^^^^^^^^^^^^^^^^^
  File "/home/schwerti/Documents/GitHub/SAMJ-CSDC26BB/SAMJ-Django-TBC/env/lib/python3.12/site-packages/django/views/generic/base.py", line 143, in dispatch
    return handler(request, *args, **kwargs)
           ^^^^^^^^^^^^^^^^^^^^^^^^^^^^^^^^^
  File "/home/schwerti/Documents/GitHub/SAMJ-CSDC26BB/SAMJ-Django-TBC/samjTBC/samj/viewClasses/restEndpoint.py", line 9, in get
    logger.info("Forwarding -> " + CallForwardingRecords.objects.all())
                ~~~~~~~~~~~~~~~~~^~~~~~~~~~~~~~~~~~~~~~~~~~~~~~~~~~~~~
TypeError: can only concatenate str (not "QuerySet") to str
[2024-06-05 19:35:16][ERROR] "GET /restEndpoint/ HTTP/1.1" 500 84604
[2024-06-05 19:37:06][WARNING] Not Found: /favicon.ico
[2024-06-05 19:37:21][WARNING] Not Found: /favicon.ico
[2024-06-05 19:38:49][ERROR] Internal Server Error: /restEndpoint/
Traceback (most recent call last):
  File "/home/schwerti/Documents/GitHub/SAMJ-CSDC26BB/SAMJ-Django-TBC/env/lib/python3.12/site-packages/django/core/handlers/exception.py", line 55, in inner
    response = get_response(request)
               ^^^^^^^^^^^^^^^^^^^^^
  File "/home/schwerti/Documents/GitHub/SAMJ-CSDC26BB/SAMJ-Django-TBC/env/lib/python3.12/site-packages/django/core/handlers/base.py", line 197, in _get_response
    response = wrapped_callback(request, *callback_args, **callback_kwargs)
               ^^^^^^^^^^^^^^^^^^^^^^^^^^^^^^^^^^^^^^^^^^^^^^^^^^^^^^^^^^^^
  File "/home/schwerti/Documents/GitHub/SAMJ-CSDC26BB/SAMJ-Django-TBC/env/lib/python3.12/site-packages/django/views/generic/base.py", line 104, in view
    return self.dispatch(request, *args, **kwargs)
           ^^^^^^^^^^^^^^^^^^^^^^^^^^^^^^^^^^^^^^^
  File "/home/schwerti/Documents/GitHub/SAMJ-CSDC26BB/SAMJ-Django-TBC/env/lib/python3.12/site-packages/django/views/generic/base.py", line 143, in dispatch
    return handler(request, *args, **kwargs)
           ^^^^^^^^^^^^^^^^^^^^^^^^^^^^^^^^^
  File "/home/schwerti/Documents/GitHub/SAMJ-CSDC26BB/SAMJ-Django-TBC/samjTBC/samj/viewClasses/restEndpoint.py", line 11, in get
    logger.info(row.destination.number)
                ^^^^^^^^^^^^^^^^^^^^^^
AttributeError: 'DestinationRecords' object has no attribute 'number'
[2024-06-05 19:38:49][ERROR] "GET /restEndpoint/ HTTP/1.1" 500 85321
[2024-06-05 19:38:54][ERROR] Internal Server Error: /restEndpoint/
Traceback (most recent call last):
  File "/home/schwerti/Documents/GitHub/SAMJ-CSDC26BB/SAMJ-Django-TBC/env/lib/python3.12/site-packages/django/core/handlers/exception.py", line 55, in inner
    response = get_response(request)
               ^^^^^^^^^^^^^^^^^^^^^
  File "/home/schwerti/Documents/GitHub/SAMJ-CSDC26BB/SAMJ-Django-TBC/env/lib/python3.12/site-packages/django/core/handlers/base.py", line 197, in _get_response
    response = wrapped_callback(request, *callback_args, **callback_kwargs)
               ^^^^^^^^^^^^^^^^^^^^^^^^^^^^^^^^^^^^^^^^^^^^^^^^^^^^^^^^^^^^
  File "/home/schwerti/Documents/GitHub/SAMJ-CSDC26BB/SAMJ-Django-TBC/env/lib/python3.12/site-packages/django/views/generic/base.py", line 104, in view
    return self.dispatch(request, *args, **kwargs)
           ^^^^^^^^^^^^^^^^^^^^^^^^^^^^^^^^^^^^^^^
  File "/home/schwerti/Documents/GitHub/SAMJ-CSDC26BB/SAMJ-Django-TBC/env/lib/python3.12/site-packages/django/views/generic/base.py", line 143, in dispatch
    return handler(request, *args, **kwargs)
           ^^^^^^^^^^^^^^^^^^^^^^^^^^^^^^^^^
  File "/home/schwerti/Documents/GitHub/SAMJ-CSDC26BB/SAMJ-Django-TBC/samjTBC/samj/viewClasses/restEndpoint.py", line 11, in get
    logger.info(row.destination.number)
                ^^^^^^^^^^^^^^^^^^^^^^
AttributeError: 'DestinationRecords' object has no attribute 'number'
[2024-06-05 19:38:54][ERROR] "GET /restEndpoint/ HTTP/1.1" 500 85321
[2024-06-05 19:38:56][ERROR] Internal Server Error: /restEndpoint/
Traceback (most recent call last):
  File "/home/schwerti/Documents/GitHub/SAMJ-CSDC26BB/SAMJ-Django-TBC/env/lib/python3.12/site-packages/django/core/handlers/exception.py", line 55, in inner
    response = get_response(request)
               ^^^^^^^^^^^^^^^^^^^^^
  File "/home/schwerti/Documents/GitHub/SAMJ-CSDC26BB/SAMJ-Django-TBC/env/lib/python3.12/site-packages/django/core/handlers/base.py", line 197, in _get_response
    response = wrapped_callback(request, *callback_args, **callback_kwargs)
               ^^^^^^^^^^^^^^^^^^^^^^^^^^^^^^^^^^^^^^^^^^^^^^^^^^^^^^^^^^^^
  File "/home/schwerti/Documents/GitHub/SAMJ-CSDC26BB/SAMJ-Django-TBC/env/lib/python3.12/site-packages/django/views/generic/base.py", line 104, in view
    return self.dispatch(request, *args, **kwargs)
           ^^^^^^^^^^^^^^^^^^^^^^^^^^^^^^^^^^^^^^^
  File "/home/schwerti/Documents/GitHub/SAMJ-CSDC26BB/SAMJ-Django-TBC/env/lib/python3.12/site-packages/django/views/generic/base.py", line 143, in dispatch
    return handler(request, *args, **kwargs)
           ^^^^^^^^^^^^^^^^^^^^^^^^^^^^^^^^^
  File "/home/schwerti/Documents/GitHub/SAMJ-CSDC26BB/SAMJ-Django-TBC/samjTBC/samj/viewClasses/restEndpoint.py", line 11, in get
    logger.info(row.destination.number)
                ^^^^^^^^^^^^^^^^^^^^^^
AttributeError: 'DestinationRecords' object has no attribute 'number'
[2024-06-05 19:38:56][ERROR] "GET /restEndpoint/ HTTP/1.1" 500 85321
[2024-06-05 19:39:39][ERROR] Internal Server Error: /restEndpoint/
Traceback (most recent call last):
  File "/home/schwerti/Documents/GitHub/SAMJ-CSDC26BB/SAMJ-Django-TBC/env/lib/python3.12/site-packages/django/core/handlers/exception.py", line 55, in inner
    response = get_response(request)
               ^^^^^^^^^^^^^^^^^^^^^
  File "/home/schwerti/Documents/GitHub/SAMJ-CSDC26BB/SAMJ-Django-TBC/env/lib/python3.12/site-packages/django/core/handlers/base.py", line 197, in _get_response
    response = wrapped_callback(request, *callback_args, **callback_kwargs)
               ^^^^^^^^^^^^^^^^^^^^^^^^^^^^^^^^^^^^^^^^^^^^^^^^^^^^^^^^^^^^
  File "/home/schwerti/Documents/GitHub/SAMJ-CSDC26BB/SAMJ-Django-TBC/env/lib/python3.12/site-packages/django/views/generic/base.py", line 104, in view
    return self.dispatch(request, *args, **kwargs)
           ^^^^^^^^^^^^^^^^^^^^^^^^^^^^^^^^^^^^^^^
  File "/home/schwerti/Documents/GitHub/SAMJ-CSDC26BB/SAMJ-Django-TBC/env/lib/python3.12/site-packages/django/views/generic/base.py", line 143, in dispatch
    return handler(request, *args, **kwargs)
           ^^^^^^^^^^^^^^^^^^^^^^^^^^^^^^^^^
  File "/home/schwerti/Documents/GitHub/SAMJ-CSDC26BB/SAMJ-Django-TBC/samjTBC/samj/viewClasses/restEndpoint.py", line 11, in get
    logger.info(row.destination.calledNumber)
                ^^^^^^^^^^^^^^^^^^^^^^^^^^^^
AttributeError: 'DestinationRecords' object has no attribute 'calledNumber'
[2024-06-05 19:39:39][ERROR] "GET /restEndpoint/ HTTP/1.1" 500 85369
[2024-06-05 19:39:58][WARNING] Not Found: /favicon.ico
[2024-06-05 19:40:11][ERROR] Internal Server Error: /restEndpoint/
Traceback (most recent call last):
  File "/home/schwerti/Documents/GitHub/SAMJ-CSDC26BB/SAMJ-Django-TBC/env/lib/python3.12/site-packages/django/core/handlers/exception.py", line 55, in inner
    response = get_response(request)
               ^^^^^^^^^^^^^^^^^^^^^
  File "/home/schwerti/Documents/GitHub/SAMJ-CSDC26BB/SAMJ-Django-TBC/env/lib/python3.12/site-packages/django/core/handlers/base.py", line 197, in _get_response
    response = wrapped_callback(request, *callback_args, **callback_kwargs)
               ^^^^^^^^^^^^^^^^^^^^^^^^^^^^^^^^^^^^^^^^^^^^^^^^^^^^^^^^^^^^
  File "/home/schwerti/Documents/GitHub/SAMJ-CSDC26BB/SAMJ-Django-TBC/env/lib/python3.12/site-packages/django/views/generic/base.py", line 104, in view
    return self.dispatch(request, *args, **kwargs)
           ^^^^^^^^^^^^^^^^^^^^^^^^^^^^^^^^^^^^^^^
  File "/home/schwerti/Documents/GitHub/SAMJ-CSDC26BB/SAMJ-Django-TBC/env/lib/python3.12/site-packages/django/views/generic/base.py", line 143, in dispatch
    return handler(request, *args, **kwargs)
           ^^^^^^^^^^^^^^^^^^^^^^^^^^^^^^^^^
  File "/home/schwerti/Documents/GitHub/SAMJ-CSDC26BB/SAMJ-Django-TBC/samjTBC/samj/viewClasses/restEndpoint.py", line 11, in get
    logger.info(row.destination.Name)
                ^^^^^^^^^^^^^^^^^^^^
AttributeError: 'DestinationRecords' object has no attribute 'Name'. Did you mean: 'name'?
[2024-06-05 19:40:11][ERROR] "GET /restEndpoint/ HTTP/1.1" 500 85305
[2024-06-05 19:40:14][ERROR] Internal Server Error: /restEndpoint/
Traceback (most recent call last):
  File "/home/schwerti/Documents/GitHub/SAMJ-CSDC26BB/SAMJ-Django-TBC/env/lib/python3.12/site-packages/django/core/handlers/exception.py", line 55, in inner
    response = get_response(request)
               ^^^^^^^^^^^^^^^^^^^^^
  File "/home/schwerti/Documents/GitHub/SAMJ-CSDC26BB/SAMJ-Django-TBC/env/lib/python3.12/site-packages/django/core/handlers/base.py", line 197, in _get_response
    response = wrapped_callback(request, *callback_args, **callback_kwargs)
               ^^^^^^^^^^^^^^^^^^^^^^^^^^^^^^^^^^^^^^^^^^^^^^^^^^^^^^^^^^^^
  File "/home/schwerti/Documents/GitHub/SAMJ-CSDC26BB/SAMJ-Django-TBC/env/lib/python3.12/site-packages/django/views/generic/base.py", line 104, in view
    return self.dispatch(request, *args, **kwargs)
           ^^^^^^^^^^^^^^^^^^^^^^^^^^^^^^^^^^^^^^^
  File "/home/schwerti/Documents/GitHub/SAMJ-CSDC26BB/SAMJ-Django-TBC/env/lib/python3.12/site-packages/django/views/generic/base.py", line 143, in dispatch
    return handler(request, *args, **kwargs)
           ^^^^^^^^^^^^^^^^^^^^^^^^^^^^^^^^^
  File "/home/schwerti/Documents/GitHub/SAMJ-CSDC26BB/SAMJ-Django-TBC/samjTBC/samj/viewClasses/restEndpoint.py", line 11, in get
    logger.info(row.destination.Name)
                ^^^^^^^^^^^^^^^^^^^^
AttributeError: 'DestinationRecords' object has no attribute 'Name'. Did you mean: 'name'?
[2024-06-05 19:40:14][ERROR] "GET /restEndpoint/ HTTP/1.1" 500 85305
[2024-06-05 19:41:16][ERROR] Internal Server Error: /restEndpoint/
Traceback (most recent call last):
  File "/home/schwerti/Documents/GitHub/SAMJ-CSDC26BB/SAMJ-Django-TBC/env/lib/python3.12/site-packages/django/core/handlers/exception.py", line 55, in inner
    response = get_response(request)
               ^^^^^^^^^^^^^^^^^^^^^
  File "/home/schwerti/Documents/GitHub/SAMJ-CSDC26BB/SAMJ-Django-TBC/env/lib/python3.12/site-packages/django/core/handlers/base.py", line 197, in _get_response
    response = wrapped_callback(request, *callback_args, **callback_kwargs)
               ^^^^^^^^^^^^^^^^^^^^^^^^^^^^^^^^^^^^^^^^^^^^^^^^^^^^^^^^^^^^
  File "/home/schwerti/Documents/GitHub/SAMJ-CSDC26BB/SAMJ-Django-TBC/env/lib/python3.12/site-packages/django/views/generic/base.py", line 104, in view
    return self.dispatch(request, *args, **kwargs)
           ^^^^^^^^^^^^^^^^^^^^^^^^^^^^^^^^^^^^^^^
  File "/home/schwerti/Documents/GitHub/SAMJ-CSDC26BB/SAMJ-Django-TBC/env/lib/python3.12/site-packages/django/views/generic/base.py", line 143, in dispatch
    return handler(request, *args, **kwargs)
           ^^^^^^^^^^^^^^^^^^^^^^^^^^^^^^^^^
  File "/home/schwerti/Documents/GitHub/SAMJ-CSDC26BB/SAMJ-Django-TBC/samjTBC/samj/viewClasses/restEndpoint.py", line 12, in get
    logger.info(row.destination.toString())
                ^^^^^^^^^^^^^^^^^^^^^^^^
AttributeError: 'DestinationRecords' object has no attribute 'toString'
[2024-06-05 19:41:16][ERROR] "GET /restEndpoint/ HTTP/1.1" 500 85339
[2024-06-05 19:42:44][ERROR] Internal Server Error: /restEndpoint/
Traceback (most recent call last):
  File "/home/schwerti/Documents/GitHub/SAMJ-CSDC26BB/SAMJ-Django-TBC/env/lib/python3.12/site-packages/django/core/handlers/exception.py", line 55, in inner
    response = get_response(request)
               ^^^^^^^^^^^^^^^^^^^^^
  File "/home/schwerti/Documents/GitHub/SAMJ-CSDC26BB/SAMJ-Django-TBC/env/lib/python3.12/site-packages/django/core/handlers/base.py", line 197, in _get_response
    response = wrapped_callback(request, *callback_args, **callback_kwargs)
               ^^^^^^^^^^^^^^^^^^^^^^^^^^^^^^^^^^^^^^^^^^^^^^^^^^^^^^^^^^^^
  File "/home/schwerti/Documents/GitHub/SAMJ-CSDC26BB/SAMJ-Django-TBC/env/lib/python3.12/site-packages/django/views/generic/base.py", line 104, in view
    return self.dispatch(request, *args, **kwargs)
           ^^^^^^^^^^^^^^^^^^^^^^^^^^^^^^^^^^^^^^^
  File "/home/schwerti/Documents/GitHub/SAMJ-CSDC26BB/SAMJ-Django-TBC/env/lib/python3.12/site-packages/django/views/generic/base.py", line 143, in dispatch
    return handler(request, *args, **kwargs)
           ^^^^^^^^^^^^^^^^^^^^^^^^^^^^^^^^^
  File "/home/schwerti/Documents/GitHub/SAMJ-CSDC26BB/SAMJ-Django-TBC/samjTBC/samj/viewClasses/restEndpoint.py", line 10, in get
    logger.info(table.get(0))
                ^^^^^^^^^^^^
  File "/home/schwerti/Documents/GitHub/SAMJ-CSDC26BB/SAMJ-Django-TBC/env/lib/python3.12/site-packages/django/db/models/query.py", line 635, in get
    clone = self._chain() if self.query.combinator else self.filter(*args, **kwargs)
                                                        ^^^^^^^^^^^^^^^^^^^^^^^^^^^^
  File "/home/schwerti/Documents/GitHub/SAMJ-CSDC26BB/SAMJ-Django-TBC/env/lib/python3.12/site-packages/django/db/models/query.py", line 1476, in filter
    return self._filter_or_exclude(False, args, kwargs)
           ^^^^^^^^^^^^^^^^^^^^^^^^^^^^^^^^^^^^^^^^^^^^
  File "/home/schwerti/Documents/GitHub/SAMJ-CSDC26BB/SAMJ-Django-TBC/env/lib/python3.12/site-packages/django/db/models/query.py", line 1494, in _filter_or_exclude
    clone._filter_or_exclude_inplace(negate, args, kwargs)
  File "/home/schwerti/Documents/GitHub/SAMJ-CSDC26BB/SAMJ-Django-TBC/env/lib/python3.12/site-packages/django/db/models/query.py", line 1501, in _filter_or_exclude_inplace
    self._query.add_q(Q(*args, **kwargs))
  File "/home/schwerti/Documents/GitHub/SAMJ-CSDC26BB/SAMJ-Django-TBC/env/lib/python3.12/site-packages/django/db/models/sql/query.py", line 1613, in add_q
    clause, _ = self._add_q(q_object, self.used_aliases)
                ^^^^^^^^^^^^^^^^^^^^^^^^^^^^^^^^^^^^^^^^
  File "/home/schwerti/Documents/GitHub/SAMJ-CSDC26BB/SAMJ-Django-TBC/env/lib/python3.12/site-packages/django/db/models/sql/query.py", line 1645, in _add_q
    child_clause, needed_inner = self.build_filter(
                                 ^^^^^^^^^^^^^^^^^^
  File "/home/schwerti/Documents/GitHub/SAMJ-CSDC26BB/SAMJ-Django-TBC/env/lib/python3.12/site-packages/django/db/models/sql/query.py", line 1492, in build_filter
    arg, value = filter_expr
    ^^^^^^^^^^
TypeError: cannot unpack non-iterable int object
[2024-06-05 19:42:44][ERROR] "GET /restEndpoint/ HTTP/1.1" 500 118829
[2024-06-05 19:42:45][ERROR] Internal Server Error: /restEndpoint/
Traceback (most recent call last):
  File "/home/schwerti/Documents/GitHub/SAMJ-CSDC26BB/SAMJ-Django-TBC/env/lib/python3.12/site-packages/django/core/handlers/exception.py", line 55, in inner
    response = get_response(request)
               ^^^^^^^^^^^^^^^^^^^^^
  File "/home/schwerti/Documents/GitHub/SAMJ-CSDC26BB/SAMJ-Django-TBC/env/lib/python3.12/site-packages/django/core/handlers/base.py", line 197, in _get_response
    response = wrapped_callback(request, *callback_args, **callback_kwargs)
               ^^^^^^^^^^^^^^^^^^^^^^^^^^^^^^^^^^^^^^^^^^^^^^^^^^^^^^^^^^^^
  File "/home/schwerti/Documents/GitHub/SAMJ-CSDC26BB/SAMJ-Django-TBC/env/lib/python3.12/site-packages/django/views/generic/base.py", line 104, in view
    return self.dispatch(request, *args, **kwargs)
           ^^^^^^^^^^^^^^^^^^^^^^^^^^^^^^^^^^^^^^^
  File "/home/schwerti/Documents/GitHub/SAMJ-CSDC26BB/SAMJ-Django-TBC/env/lib/python3.12/site-packages/django/views/generic/base.py", line 143, in dispatch
    return handler(request, *args, **kwargs)
           ^^^^^^^^^^^^^^^^^^^^^^^^^^^^^^^^^
  File "/home/schwerti/Documents/GitHub/SAMJ-CSDC26BB/SAMJ-Django-TBC/samjTBC/samj/viewClasses/restEndpoint.py", line 10, in get
    logger.info(table.get(0))
                ^^^^^^^^^^^^
  File "/home/schwerti/Documents/GitHub/SAMJ-CSDC26BB/SAMJ-Django-TBC/env/lib/python3.12/site-packages/django/db/models/query.py", line 635, in get
    clone = self._chain() if self.query.combinator else self.filter(*args, **kwargs)
                                                        ^^^^^^^^^^^^^^^^^^^^^^^^^^^^
  File "/home/schwerti/Documents/GitHub/SAMJ-CSDC26BB/SAMJ-Django-TBC/env/lib/python3.12/site-packages/django/db/models/query.py", line 1476, in filter
    return self._filter_or_exclude(False, args, kwargs)
           ^^^^^^^^^^^^^^^^^^^^^^^^^^^^^^^^^^^^^^^^^^^^
  File "/home/schwerti/Documents/GitHub/SAMJ-CSDC26BB/SAMJ-Django-TBC/env/lib/python3.12/site-packages/django/db/models/query.py", line 1494, in _filter_or_exclude
    clone._filter_or_exclude_inplace(negate, args, kwargs)
  File "/home/schwerti/Documents/GitHub/SAMJ-CSDC26BB/SAMJ-Django-TBC/env/lib/python3.12/site-packages/django/db/models/query.py", line 1501, in _filter_or_exclude_inplace
    self._query.add_q(Q(*args, **kwargs))
  File "/home/schwerti/Documents/GitHub/SAMJ-CSDC26BB/SAMJ-Django-TBC/env/lib/python3.12/site-packages/django/db/models/sql/query.py", line 1613, in add_q
    clause, _ = self._add_q(q_object, self.used_aliases)
                ^^^^^^^^^^^^^^^^^^^^^^^^^^^^^^^^^^^^^^^^
  File "/home/schwerti/Documents/GitHub/SAMJ-CSDC26BB/SAMJ-Django-TBC/env/lib/python3.12/site-packages/django/db/models/sql/query.py", line 1645, in _add_q
    child_clause, needed_inner = self.build_filter(
                                 ^^^^^^^^^^^^^^^^^^
  File "/home/schwerti/Documents/GitHub/SAMJ-CSDC26BB/SAMJ-Django-TBC/env/lib/python3.12/site-packages/django/db/models/sql/query.py", line 1492, in build_filter
    arg, value = filter_expr
    ^^^^^^^^^^
TypeError: cannot unpack non-iterable int object
[2024-06-05 19:42:45][ERROR] "GET /restEndpoint/ HTTP/1.1" 500 118829
[2024-06-05 19:42:59][ERROR] Internal Server Error: /restEndpoint/
Traceback (most recent call last):
  File "/home/schwerti/Documents/GitHub/SAMJ-CSDC26BB/SAMJ-Django-TBC/env/lib/python3.12/site-packages/django/core/handlers/exception.py", line 55, in inner
    response = get_response(request)
               ^^^^^^^^^^^^^^^^^^^^^
  File "/home/schwerti/Documents/GitHub/SAMJ-CSDC26BB/SAMJ-Django-TBC/env/lib/python3.12/site-packages/django/core/handlers/base.py", line 197, in _get_response
    response = wrapped_callback(request, *callback_args, **callback_kwargs)
               ^^^^^^^^^^^^^^^^^^^^^^^^^^^^^^^^^^^^^^^^^^^^^^^^^^^^^^^^^^^^
  File "/home/schwerti/Documents/GitHub/SAMJ-CSDC26BB/SAMJ-Django-TBC/env/lib/python3.12/site-packages/django/views/generic/base.py", line 104, in view
    return self.dispatch(request, *args, **kwargs)
           ^^^^^^^^^^^^^^^^^^^^^^^^^^^^^^^^^^^^^^^
  File "/home/schwerti/Documents/GitHub/SAMJ-CSDC26BB/SAMJ-Django-TBC/env/lib/python3.12/site-packages/django/views/generic/base.py", line 143, in dispatch
    return handler(request, *args, **kwargs)
           ^^^^^^^^^^^^^^^^^^^^^^^^^^^^^^^^^
  File "/home/schwerti/Documents/GitHub/SAMJ-CSDC26BB/SAMJ-Django-TBC/samjTBC/samj/viewClasses/restEndpoint.py", line 10, in get
    logger.info(table.get(0).destination)
                ^^^^^^^^^^^^
  File "/home/schwerti/Documents/GitHub/SAMJ-CSDC26BB/SAMJ-Django-TBC/env/lib/python3.12/site-packages/django/db/models/query.py", line 635, in get
    clone = self._chain() if self.query.combinator else self.filter(*args, **kwargs)
                                                        ^^^^^^^^^^^^^^^^^^^^^^^^^^^^
  File "/home/schwerti/Documents/GitHub/SAMJ-CSDC26BB/SAMJ-Django-TBC/env/lib/python3.12/site-packages/django/db/models/query.py", line 1476, in filter
    return self._filter_or_exclude(False, args, kwargs)
           ^^^^^^^^^^^^^^^^^^^^^^^^^^^^^^^^^^^^^^^^^^^^
  File "/home/schwerti/Documents/GitHub/SAMJ-CSDC26BB/SAMJ-Django-TBC/env/lib/python3.12/site-packages/django/db/models/query.py", line 1494, in _filter_or_exclude
    clone._filter_or_exclude_inplace(negate, args, kwargs)
  File "/home/schwerti/Documents/GitHub/SAMJ-CSDC26BB/SAMJ-Django-TBC/env/lib/python3.12/site-packages/django/db/models/query.py", line 1501, in _filter_or_exclude_inplace
    self._query.add_q(Q(*args, **kwargs))
  File "/home/schwerti/Documents/GitHub/SAMJ-CSDC26BB/SAMJ-Django-TBC/env/lib/python3.12/site-packages/django/db/models/sql/query.py", line 1613, in add_q
    clause, _ = self._add_q(q_object, self.used_aliases)
                ^^^^^^^^^^^^^^^^^^^^^^^^^^^^^^^^^^^^^^^^
  File "/home/schwerti/Documents/GitHub/SAMJ-CSDC26BB/SAMJ-Django-TBC/env/lib/python3.12/site-packages/django/db/models/sql/query.py", line 1645, in _add_q
    child_clause, needed_inner = self.build_filter(
                                 ^^^^^^^^^^^^^^^^^^
  File "/home/schwerti/Documents/GitHub/SAMJ-CSDC26BB/SAMJ-Django-TBC/env/lib/python3.12/site-packages/django/db/models/sql/query.py", line 1492, in build_filter
    arg, value = filter_expr
    ^^^^^^^^^^
TypeError: cannot unpack non-iterable int object
[2024-06-05 19:42:59][ERROR] "GET /restEndpoint/ HTTP/1.1" 500 118853
[2024-06-05 19:49:59][WARNING] Not Found: /favicon.ico
[2024-06-05 19:51:09][ERROR] Internal Server Error: /restEndpoint/
Traceback (most recent call last):
  File "/home/schwerti/Documents/GitHub/SAMJ-CSDC26BB/SAMJ-Django-TBC/env/lib/python3.12/site-packages/django/core/handlers/exception.py", line 55, in inner
    response = get_response(request)
               ^^^^^^^^^^^^^^^^^^^^^
  File "/home/schwerti/Documents/GitHub/SAMJ-CSDC26BB/SAMJ-Django-TBC/env/lib/python3.12/site-packages/django/core/handlers/base.py", line 197, in _get_response
    response = wrapped_callback(request, *callback_args, **callback_kwargs)
               ^^^^^^^^^^^^^^^^^^^^^^^^^^^^^^^^^^^^^^^^^^^^^^^^^^^^^^^^^^^^
  File "/home/schwerti/Documents/GitHub/SAMJ-CSDC26BB/SAMJ-Django-TBC/env/lib/python3.12/site-packages/django/views/generic/base.py", line 104, in view
    return self.dispatch(request, *args, **kwargs)
           ^^^^^^^^^^^^^^^^^^^^^^^^^^^^^^^^^^^^^^^
  File "/home/schwerti/Documents/GitHub/SAMJ-CSDC26BB/SAMJ-Django-TBC/env/lib/python3.12/site-packages/django/views/generic/base.py", line 143, in dispatch
    return handler(request, *args, **kwargs)
           ^^^^^^^^^^^^^^^^^^^^^^^^^^^^^^^^^
  File "/home/schwerti/Documents/GitHub/SAMJ-CSDC26BB/SAMJ-Django-TBC/samjTBC/samj/viewClasses/restEndpoint.py", line 10, in get
    logger.info(table.filter(CalledNumber="+4367763106443"))
                ^^^^^^^^^^^^^^^^^^^^^^^^^^^^^^^^^^^^^^^^^^^
  File "/home/schwerti/Documents/GitHub/SAMJ-CSDC26BB/SAMJ-Django-TBC/env/lib/python3.12/site-packages/django/db/models/query.py", line 1476, in filter
    return self._filter_or_exclude(False, args, kwargs)
           ^^^^^^^^^^^^^^^^^^^^^^^^^^^^^^^^^^^^^^^^^^^^
  File "/home/schwerti/Documents/GitHub/SAMJ-CSDC26BB/SAMJ-Django-TBC/env/lib/python3.12/site-packages/django/db/models/query.py", line 1494, in _filter_or_exclude
    clone._filter_or_exclude_inplace(negate, args, kwargs)
  File "/home/schwerti/Documents/GitHub/SAMJ-CSDC26BB/SAMJ-Django-TBC/env/lib/python3.12/site-packages/django/db/models/query.py", line 1501, in _filter_or_exclude_inplace
    self._query.add_q(Q(*args, **kwargs))
  File "/home/schwerti/Documents/GitHub/SAMJ-CSDC26BB/SAMJ-Django-TBC/env/lib/python3.12/site-packages/django/db/models/sql/query.py", line 1613, in add_q
    clause, _ = self._add_q(q_object, self.used_aliases)
                ^^^^^^^^^^^^^^^^^^^^^^^^^^^^^^^^^^^^^^^^
  File "/home/schwerti/Documents/GitHub/SAMJ-CSDC26BB/SAMJ-Django-TBC/env/lib/python3.12/site-packages/django/db/models/sql/query.py", line 1645, in _add_q
    child_clause, needed_inner = self.build_filter(
                                 ^^^^^^^^^^^^^^^^^^
  File "/home/schwerti/Documents/GitHub/SAMJ-CSDC26BB/SAMJ-Django-TBC/env/lib/python3.12/site-packages/django/db/models/sql/query.py", line 1495, in build_filter
    lookups, parts, reffed_expression = self.solve_lookup_type(arg, summarize)
                                        ^^^^^^^^^^^^^^^^^^^^^^^^^^^^^^^^^^^^^^
  File "/home/schwerti/Documents/GitHub/SAMJ-CSDC26BB/SAMJ-Django-TBC/env/lib/python3.12/site-packages/django/db/models/sql/query.py", line 1307, in solve_lookup_type
    _, field, _, lookup_parts = self.names_to_path(lookup_splitted, self.get_meta())
                                ^^^^^^^^^^^^^^^^^^^^^^^^^^^^^^^^^^^^^^^^^^^^^^^^^^^^
  File "/home/schwerti/Documents/GitHub/SAMJ-CSDC26BB/SAMJ-Django-TBC/env/lib/python3.12/site-packages/django/db/models/sql/query.py", line 1772, in names_to_path
    raise FieldError(
django.core.exceptions.FieldError: Cannot resolve keyword 'CalledNumber' into field. Choices are: calledNumber, destination, destination_id, endDate, id, startDate, username
[2024-06-05 19:51:09][ERROR] "GET /restEndpoint/ HTTP/1.1" 500 126943
[2024-06-05 19:54:17][ERROR] Internal Server Error: /restEndpoint/
Traceback (most recent call last):
  File "/home/schwerti/Documents/GitHub/SAMJ-CSDC26BB/SAMJ-Django-TBC/env/lib/python3.12/site-packages/django/core/handlers/exception.py", line 55, in inner
    response = get_response(request)
               ^^^^^^^^^^^^^^^^^^^^^
  File "/home/schwerti/Documents/GitHub/SAMJ-CSDC26BB/SAMJ-Django-TBC/env/lib/python3.12/site-packages/django/core/handlers/base.py", line 197, in _get_response
    response = wrapped_callback(request, *callback_args, **callback_kwargs)
               ^^^^^^^^^^^^^^^^^^^^^^^^^^^^^^^^^^^^^^^^^^^^^^^^^^^^^^^^^^^^
  File "/home/schwerti/Documents/GitHub/SAMJ-CSDC26BB/SAMJ-Django-TBC/env/lib/python3.12/site-packages/django/views/generic/base.py", line 104, in view
    return self.dispatch(request, *args, **kwargs)
           ^^^^^^^^^^^^^^^^^^^^^^^^^^^^^^^^^^^^^^^
  File "/home/schwerti/Documents/GitHub/SAMJ-CSDC26BB/SAMJ-Django-TBC/env/lib/python3.12/site-packages/django/views/generic/base.py", line 143, in dispatch
    return handler(request, *args, **kwargs)
           ^^^^^^^^^^^^^^^^^^^^^^^^^^^^^^^^^
  File "/home/schwerti/Documents/GitHub/SAMJ-CSDC26BB/SAMJ-Django-TBC/samjTBC/samj/viewClasses/restEndpoint.py", line 10, in get
    logger.info(table[0]["destination"])
                ~~~~~~~~^^^^^^^^^^^^^^^
TypeError: 'CallForwardingRecords' object is not subscriptable
[2024-06-05 19:54:17][ERROR] "GET /restEndpoint/ HTTP/1.1" 500 85310
[2024-06-05 19:55:36][ERROR] Internal Server Error: /restEndpoint/
Traceback (most recent call last):
  File "/home/schwerti/Documents/GitHub/SAMJ-CSDC26BB/SAMJ-Django-TBC/env/lib/python3.12/site-packages/django/core/handlers/exception.py", line 55, in inner
    response = get_response(request)
               ^^^^^^^^^^^^^^^^^^^^^
  File "/home/schwerti/Documents/GitHub/SAMJ-CSDC26BB/SAMJ-Django-TBC/env/lib/python3.12/site-packages/django/core/handlers/base.py", line 197, in _get_response
    response = wrapped_callback(request, *callback_args, **callback_kwargs)
               ^^^^^^^^^^^^^^^^^^^^^^^^^^^^^^^^^^^^^^^^^^^^^^^^^^^^^^^^^^^^
  File "/home/schwerti/Documents/GitHub/SAMJ-CSDC26BB/SAMJ-Django-TBC/env/lib/python3.12/site-packages/django/views/generic/base.py", line 104, in view
    return self.dispatch(request, *args, **kwargs)
           ^^^^^^^^^^^^^^^^^^^^^^^^^^^^^^^^^^^^^^^
  File "/home/schwerti/Documents/GitHub/SAMJ-CSDC26BB/SAMJ-Django-TBC/env/lib/python3.12/site-packages/django/views/generic/base.py", line 143, in dispatch
    return handler(request, *args, **kwargs)
           ^^^^^^^^^^^^^^^^^^^^^^^^^^^^^^^^^
  File "/home/schwerti/Documents/GitHub/SAMJ-CSDC26BB/SAMJ-Django-TBC/samjTBC/samj/viewClasses/restEndpoint.py", line 10, in get
    logger.info(table[0]["destination"])
                ~~~~~~~~^^^^^^^^^^^^^^^
KeyError: 'destination'
[2024-06-05 19:55:36][ERROR] "GET /restEndpoint/ HTTP/1.1" 500 85367
[2024-06-05 19:58:16][WARNING] Not Found: /favicon.ico
[2024-06-05 20:00:59][WARNING] Not Found: /restEndpoint/+4367763106443
[2024-06-05 20:00:59][WARNING] "GET /restEndpoint/+4367763106443 HTTP/1.1" 404 3354
[2024-06-05 20:10:27][WARNING] Not Found: /restEndpoint/number=+4367763106443
[2024-06-05 20:10:27][WARNING] "GET /restEndpoint/number=+4367763106443 HTTP/1.1" 404 3377
[2024-06-05 20:14:56][ERROR] Internal Server Error: /restEndpoint/
Traceback (most recent call last):
  File "/home/schwerti/Documents/GitHub/SAMJ-CSDC26BB/SAMJ-Django-TBC/env/lib/python3.12/site-packages/django/core/handlers/exception.py", line 55, in inner
    response = get_response(request)
               ^^^^^^^^^^^^^^^^^^^^^
  File "/home/schwerti/Documents/GitHub/SAMJ-CSDC26BB/SAMJ-Django-TBC/env/lib/python3.12/site-packages/django/core/handlers/base.py", line 197, in _get_response
    response = wrapped_callback(request, *callback_args, **callback_kwargs)
               ^^^^^^^^^^^^^^^^^^^^^^^^^^^^^^^^^^^^^^^^^^^^^^^^^^^^^^^^^^^^
  File "/home/schwerti/Documents/GitHub/SAMJ-CSDC26BB/SAMJ-Django-TBC/env/lib/python3.12/site-packages/django/views/generic/base.py", line 104, in view
    return self.dispatch(request, *args, **kwargs)
           ^^^^^^^^^^^^^^^^^^^^^^^^^^^^^^^^^^^^^^^
  File "/home/schwerti/Documents/GitHub/SAMJ-CSDC26BB/SAMJ-Django-TBC/env/lib/python3.12/site-packages/django/views/generic/base.py", line 143, in dispatch
    return handler(request, *args, **kwargs)
           ^^^^^^^^^^^^^^^^^^^^^^^^^^^^^^^^^
  File "/home/schwerti/Documents/GitHub/SAMJ-CSDC26BB/SAMJ-Django-TBC/samjTBC/samj/viewClasses/restEndpoint.py", line 12, in get
    dest = CallForwardingRecords.objects.all().filter(destination__icontains=query).values()
           ^^^^^^^^^^^^^^^^^^^^^^^^^^^^^^^^^^^^^^^^^^^^^^^^^^^^^^^^^^^^^^^^^^^^^^^^
  File "/home/schwerti/Documents/GitHub/SAMJ-CSDC26BB/SAMJ-Django-TBC/env/lib/python3.12/site-packages/django/db/models/query.py", line 1476, in filter
    return self._filter_or_exclude(False, args, kwargs)
           ^^^^^^^^^^^^^^^^^^^^^^^^^^^^^^^^^^^^^^^^^^^^
  File "/home/schwerti/Documents/GitHub/SAMJ-CSDC26BB/SAMJ-Django-TBC/env/lib/python3.12/site-packages/django/db/models/query.py", line 1494, in _filter_or_exclude
    clone._filter_or_exclude_inplace(negate, args, kwargs)
  File "/home/schwerti/Documents/GitHub/SAMJ-CSDC26BB/SAMJ-Django-TBC/env/lib/python3.12/site-packages/django/db/models/query.py", line 1501, in _filter_or_exclude_inplace
    self._query.add_q(Q(*args, **kwargs))
  File "/home/schwerti/Documents/GitHub/SAMJ-CSDC26BB/SAMJ-Django-TBC/env/lib/python3.12/site-packages/django/db/models/sql/query.py", line 1613, in add_q
    clause, _ = self._add_q(q_object, self.used_aliases)
                ^^^^^^^^^^^^^^^^^^^^^^^^^^^^^^^^^^^^^^^^
  File "/home/schwerti/Documents/GitHub/SAMJ-CSDC26BB/SAMJ-Django-TBC/env/lib/python3.12/site-packages/django/db/models/sql/query.py", line 1645, in _add_q
    child_clause, needed_inner = self.build_filter(
                                 ^^^^^^^^^^^^^^^^^^
  File "/home/schwerti/Documents/GitHub/SAMJ-CSDC26BB/SAMJ-Django-TBC/env/lib/python3.12/site-packages/django/db/models/sql/query.py", line 1559, in build_filter
    condition = self.build_lookup(lookups, col, value)
                ^^^^^^^^^^^^^^^^^^^^^^^^^^^^^^^^^^^^^^
  File "/home/schwerti/Documents/GitHub/SAMJ-CSDC26BB/SAMJ-Django-TBC/env/lib/python3.12/site-packages/django/db/models/sql/query.py", line 1383, in build_lookup
    lhs = self.try_transform(lhs, lookup_name)
          ^^^^^^^^^^^^^^^^^^^^^^^^^^^^^^^^^^^^
  File "/home/schwerti/Documents/GitHub/SAMJ-CSDC26BB/SAMJ-Django-TBC/env/lib/python3.12/site-packages/django/db/models/sql/query.py", line 1427, in try_transform
    raise FieldError(
django.core.exceptions.FieldError: Unsupported lookup 'icontains' for ForeignKey or join on the field not permitted.
[2024-06-05 20:14:56][ERROR] "GET /restEndpoint/?number\=+4367763106443 HTTP/1.1" 500 126717
[2024-06-17 16:59:01][ERROR] Internal Server Error: /restEndpoint/
Traceback (most recent call last):
  File "/home/schwerti/Documents/GitHub/SAMJ-CSDC26BB/SAMJ-Django-TBC/env/lib/python3.12/site-packages/django/core/handlers/exception.py", line 55, in inner
    response = get_response(request)
               ^^^^^^^^^^^^^^^^^^^^^
  File "/home/schwerti/Documents/GitHub/SAMJ-CSDC26BB/SAMJ-Django-TBC/env/lib/python3.12/site-packages/django/core/handlers/base.py", line 197, in _get_response
    response = wrapped_callback(request, *callback_args, **callback_kwargs)
               ^^^^^^^^^^^^^^^^^^^^^^^^^^^^^^^^^^^^^^^^^^^^^^^^^^^^^^^^^^^^
  File "/home/schwerti/Documents/GitHub/SAMJ-CSDC26BB/SAMJ-Django-TBC/env/lib/python3.12/site-packages/django/views/generic/base.py", line 104, in view
    return self.dispatch(request, *args, **kwargs)
           ^^^^^^^^^^^^^^^^^^^^^^^^^^^^^^^^^^^^^^^
  File "/home/schwerti/Documents/GitHub/SAMJ-CSDC26BB/SAMJ-Django-TBC/env/lib/python3.12/site-packages/django/views/generic/base.py", line 143, in dispatch
    return handler(request, *args, **kwargs)
           ^^^^^^^^^^^^^^^^^^^^^^^^^^^^^^^^^
  File "/home/schwerti/Documents/GitHub/SAMJ-CSDC26BB/SAMJ-Django-TBC/samjTBC/samj/viewClasses/restEndpoint.py", line 12, in get
    dest = CallForwardingRecords.objects.all().filter(destination__icontains=query).values()
           ^^^^^^^^^^^^^^^^^^^^^^^^^^^^^^^^^^^^^^^^^^^^^^^^^^^^^^^^^^^^^^^^^^^^^^^^
  File "/home/schwerti/Documents/GitHub/SAMJ-CSDC26BB/SAMJ-Django-TBC/env/lib/python3.12/site-packages/django/db/models/query.py", line 1476, in filter
    return self._filter_or_exclude(False, args, kwargs)
           ^^^^^^^^^^^^^^^^^^^^^^^^^^^^^^^^^^^^^^^^^^^^
  File "/home/schwerti/Documents/GitHub/SAMJ-CSDC26BB/SAMJ-Django-TBC/env/lib/python3.12/site-packages/django/db/models/query.py", line 1494, in _filter_or_exclude
    clone._filter_or_exclude_inplace(negate, args, kwargs)
  File "/home/schwerti/Documents/GitHub/SAMJ-CSDC26BB/SAMJ-Django-TBC/env/lib/python3.12/site-packages/django/db/models/query.py", line 1501, in _filter_or_exclude_inplace
    self._query.add_q(Q(*args, **kwargs))
  File "/home/schwerti/Documents/GitHub/SAMJ-CSDC26BB/SAMJ-Django-TBC/env/lib/python3.12/site-packages/django/db/models/sql/query.py", line 1613, in add_q
    clause, _ = self._add_q(q_object, self.used_aliases)
                ^^^^^^^^^^^^^^^^^^^^^^^^^^^^^^^^^^^^^^^^
  File "/home/schwerti/Documents/GitHub/SAMJ-CSDC26BB/SAMJ-Django-TBC/env/lib/python3.12/site-packages/django/db/models/sql/query.py", line 1645, in _add_q
    child_clause, needed_inner = self.build_filter(
                                 ^^^^^^^^^^^^^^^^^^
  File "/home/schwerti/Documents/GitHub/SAMJ-CSDC26BB/SAMJ-Django-TBC/env/lib/python3.12/site-packages/django/db/models/sql/query.py", line 1559, in build_filter
    condition = self.build_lookup(lookups, col, value)
                ^^^^^^^^^^^^^^^^^^^^^^^^^^^^^^^^^^^^^^
  File "/home/schwerti/Documents/GitHub/SAMJ-CSDC26BB/SAMJ-Django-TBC/env/lib/python3.12/site-packages/django/db/models/sql/query.py", line 1383, in build_lookup
    lhs = self.try_transform(lhs, lookup_name)
          ^^^^^^^^^^^^^^^^^^^^^^^^^^^^^^^^^^^^
  File "/home/schwerti/Documents/GitHub/SAMJ-CSDC26BB/SAMJ-Django-TBC/env/lib/python3.12/site-packages/django/db/models/sql/query.py", line 1427, in try_transform
    raise FieldError(
django.core.exceptions.FieldError: Unsupported lookup 'icontains' for ForeignKey or join on the field not permitted.
[2024-06-17 16:59:01][ERROR] "GET /restEndpoint/?number\=+4367763106443 HTTP/1.1" 500 126717
[2024-06-17 16:59:34][ERROR] Internal Server Error: /restEndpoint/
Traceback (most recent call last):
  File "/home/schwerti/Documents/GitHub/SAMJ-CSDC26BB/SAMJ-Django-TBC/env/lib/python3.12/site-packages/django/core/handlers/exception.py", line 55, in inner
    response = get_response(request)
               ^^^^^^^^^^^^^^^^^^^^^
  File "/home/schwerti/Documents/GitHub/SAMJ-CSDC26BB/SAMJ-Django-TBC/env/lib/python3.12/site-packages/django/core/handlers/base.py", line 197, in _get_response
    response = wrapped_callback(request, *callback_args, **callback_kwargs)
               ^^^^^^^^^^^^^^^^^^^^^^^^^^^^^^^^^^^^^^^^^^^^^^^^^^^^^^^^^^^^
  File "/home/schwerti/Documents/GitHub/SAMJ-CSDC26BB/SAMJ-Django-TBC/env/lib/python3.12/site-packages/django/views/generic/base.py", line 104, in view
    return self.dispatch(request, *args, **kwargs)
           ^^^^^^^^^^^^^^^^^^^^^^^^^^^^^^^^^^^^^^^
  File "/home/schwerti/Documents/GitHub/SAMJ-CSDC26BB/SAMJ-Django-TBC/env/lib/python3.12/site-packages/django/views/generic/base.py", line 143, in dispatch
    return handler(request, *args, **kwargs)
           ^^^^^^^^^^^^^^^^^^^^^^^^^^^^^^^^^
  File "/home/schwerti/Documents/GitHub/SAMJ-CSDC26BB/SAMJ-Django-TBC/samjTBC/samj/viewClasses/restEndpoint.py", line 12, in get
    dest = CallForwardingRecords.objects.all().filter(destination__icontains=query).values()
           ^^^^^^^^^^^^^^^^^^^^^^^^^^^^^^^^^^^^^^^^^^^^^^^^^^^^^^^^^^^^^^^^^^^^^^^^
  File "/home/schwerti/Documents/GitHub/SAMJ-CSDC26BB/SAMJ-Django-TBC/env/lib/python3.12/site-packages/django/db/models/query.py", line 1476, in filter
    return self._filter_or_exclude(False, args, kwargs)
           ^^^^^^^^^^^^^^^^^^^^^^^^^^^^^^^^^^^^^^^^^^^^
  File "/home/schwerti/Documents/GitHub/SAMJ-CSDC26BB/SAMJ-Django-TBC/env/lib/python3.12/site-packages/django/db/models/query.py", line 1494, in _filter_or_exclude
    clone._filter_or_exclude_inplace(negate, args, kwargs)
  File "/home/schwerti/Documents/GitHub/SAMJ-CSDC26BB/SAMJ-Django-TBC/env/lib/python3.12/site-packages/django/db/models/query.py", line 1501, in _filter_or_exclude_inplace
    self._query.add_q(Q(*args, **kwargs))
  File "/home/schwerti/Documents/GitHub/SAMJ-CSDC26BB/SAMJ-Django-TBC/env/lib/python3.12/site-packages/django/db/models/sql/query.py", line 1613, in add_q
    clause, _ = self._add_q(q_object, self.used_aliases)
                ^^^^^^^^^^^^^^^^^^^^^^^^^^^^^^^^^^^^^^^^
  File "/home/schwerti/Documents/GitHub/SAMJ-CSDC26BB/SAMJ-Django-TBC/env/lib/python3.12/site-packages/django/db/models/sql/query.py", line 1645, in _add_q
    child_clause, needed_inner = self.build_filter(
                                 ^^^^^^^^^^^^^^^^^^
  File "/home/schwerti/Documents/GitHub/SAMJ-CSDC26BB/SAMJ-Django-TBC/env/lib/python3.12/site-packages/django/db/models/sql/query.py", line 1559, in build_filter
    condition = self.build_lookup(lookups, col, value)
                ^^^^^^^^^^^^^^^^^^^^^^^^^^^^^^^^^^^^^^
  File "/home/schwerti/Documents/GitHub/SAMJ-CSDC26BB/SAMJ-Django-TBC/env/lib/python3.12/site-packages/django/db/models/sql/query.py", line 1383, in build_lookup
    lhs = self.try_transform(lhs, lookup_name)
          ^^^^^^^^^^^^^^^^^^^^^^^^^^^^^^^^^^^^
  File "/home/schwerti/Documents/GitHub/SAMJ-CSDC26BB/SAMJ-Django-TBC/env/lib/python3.12/site-packages/django/db/models/sql/query.py", line 1427, in try_transform
    raise FieldError(
django.core.exceptions.FieldError: Unsupported lookup 'icontains' for ForeignKey or join on the field not permitted.
[2024-06-17 16:59:34][ERROR] "GET /restEndpoint/?number\=+4367763106443 HTTP/1.1" 500 126717
[2024-06-17 16:59:59][ERROR] Internal Server Error: /restEndpoint/
Traceback (most recent call last):
  File "/home/schwerti/Documents/GitHub/SAMJ-CSDC26BB/SAMJ-Django-TBC/env/lib/python3.12/site-packages/django/core/handlers/exception.py", line 55, in inner
    response = get_response(request)
               ^^^^^^^^^^^^^^^^^^^^^
  File "/home/schwerti/Documents/GitHub/SAMJ-CSDC26BB/SAMJ-Django-TBC/env/lib/python3.12/site-packages/django/core/handlers/base.py", line 197, in _get_response
    response = wrapped_callback(request, *callback_args, **callback_kwargs)
               ^^^^^^^^^^^^^^^^^^^^^^^^^^^^^^^^^^^^^^^^^^^^^^^^^^^^^^^^^^^^
  File "/home/schwerti/Documents/GitHub/SAMJ-CSDC26BB/SAMJ-Django-TBC/env/lib/python3.12/site-packages/django/views/generic/base.py", line 104, in view
    return self.dispatch(request, *args, **kwargs)
           ^^^^^^^^^^^^^^^^^^^^^^^^^^^^^^^^^^^^^^^
  File "/home/schwerti/Documents/GitHub/SAMJ-CSDC26BB/SAMJ-Django-TBC/env/lib/python3.12/site-packages/django/views/generic/base.py", line 143, in dispatch
    return handler(request, *args, **kwargs)
           ^^^^^^^^^^^^^^^^^^^^^^^^^^^^^^^^^
  File "/home/schwerti/Documents/GitHub/SAMJ-CSDC26BB/SAMJ-Django-TBC/samjTBC/samj/viewClasses/restEndpoint.py", line 12, in get
    dest = CallForwardingRecords.objects.all().filter(destination__icontains=query).values()
           ^^^^^^^^^^^^^^^^^^^^^^^^^^^^^^^^^^^^^^^^^^^^^^^^^^^^^^^^^^^^^^^^^^^^^^^^
  File "/home/schwerti/Documents/GitHub/SAMJ-CSDC26BB/SAMJ-Django-TBC/env/lib/python3.12/site-packages/django/db/models/query.py", line 1476, in filter
    return self._filter_or_exclude(False, args, kwargs)
           ^^^^^^^^^^^^^^^^^^^^^^^^^^^^^^^^^^^^^^^^^^^^
  File "/home/schwerti/Documents/GitHub/SAMJ-CSDC26BB/SAMJ-Django-TBC/env/lib/python3.12/site-packages/django/db/models/query.py", line 1494, in _filter_or_exclude
    clone._filter_or_exclude_inplace(negate, args, kwargs)
  File "/home/schwerti/Documents/GitHub/SAMJ-CSDC26BB/SAMJ-Django-TBC/env/lib/python3.12/site-packages/django/db/models/query.py", line 1501, in _filter_or_exclude_inplace
    self._query.add_q(Q(*args, **kwargs))
  File "/home/schwerti/Documents/GitHub/SAMJ-CSDC26BB/SAMJ-Django-TBC/env/lib/python3.12/site-packages/django/db/models/sql/query.py", line 1613, in add_q
    clause, _ = self._add_q(q_object, self.used_aliases)
                ^^^^^^^^^^^^^^^^^^^^^^^^^^^^^^^^^^^^^^^^
  File "/home/schwerti/Documents/GitHub/SAMJ-CSDC26BB/SAMJ-Django-TBC/env/lib/python3.12/site-packages/django/db/models/sql/query.py", line 1645, in _add_q
    child_clause, needed_inner = self.build_filter(
                                 ^^^^^^^^^^^^^^^^^^
  File "/home/schwerti/Documents/GitHub/SAMJ-CSDC26BB/SAMJ-Django-TBC/env/lib/python3.12/site-packages/django/db/models/sql/query.py", line 1559, in build_filter
    condition = self.build_lookup(lookups, col, value)
                ^^^^^^^^^^^^^^^^^^^^^^^^^^^^^^^^^^^^^^
  File "/home/schwerti/Documents/GitHub/SAMJ-CSDC26BB/SAMJ-Django-TBC/env/lib/python3.12/site-packages/django/db/models/sql/query.py", line 1383, in build_lookup
    lhs = self.try_transform(lhs, lookup_name)
          ^^^^^^^^^^^^^^^^^^^^^^^^^^^^^^^^^^^^
  File "/home/schwerti/Documents/GitHub/SAMJ-CSDC26BB/SAMJ-Django-TBC/env/lib/python3.12/site-packages/django/db/models/sql/query.py", line 1427, in try_transform
    raise FieldError(
django.core.exceptions.FieldError: Unsupported lookup 'icontains' for ForeignKey or join on the field not permitted.
[2024-06-17 16:59:59][ERROR] "GET /restEndpoint/?number=+4367763106443 HTTP/1.1" 500 129365
[2024-06-17 17:00:00][WARNING] Not Found: /favicon.ico
[2024-06-17 17:00:43][ERROR] Internal Server Error: /restEndpoint/
Traceback (most recent call last):
  File "/home/schwerti/Documents/GitHub/SAMJ-CSDC26BB/SAMJ-Django-TBC/env/lib/python3.12/site-packages/django/core/handlers/exception.py", line 55, in inner
    response = get_response(request)
               ^^^^^^^^^^^^^^^^^^^^^
  File "/home/schwerti/Documents/GitHub/SAMJ-CSDC26BB/SAMJ-Django-TBC/env/lib/python3.12/site-packages/django/core/handlers/base.py", line 197, in _get_response
    response = wrapped_callback(request, *callback_args, **callback_kwargs)
               ^^^^^^^^^^^^^^^^^^^^^^^^^^^^^^^^^^^^^^^^^^^^^^^^^^^^^^^^^^^^
  File "/home/schwerti/Documents/GitHub/SAMJ-CSDC26BB/SAMJ-Django-TBC/env/lib/python3.12/site-packages/django/views/generic/base.py", line 104, in view
    return self.dispatch(request, *args, **kwargs)
           ^^^^^^^^^^^^^^^^^^^^^^^^^^^^^^^^^^^^^^^
  File "/home/schwerti/Documents/GitHub/SAMJ-CSDC26BB/SAMJ-Django-TBC/env/lib/python3.12/site-packages/django/views/generic/base.py", line 143, in dispatch
    return handler(request, *args, **kwargs)
           ^^^^^^^^^^^^^^^^^^^^^^^^^^^^^^^^^
  File "/home/schwerti/Documents/GitHub/SAMJ-CSDC26BB/SAMJ-Django-TBC/samjTBC/samj/viewClasses/restEndpoint.py", line 12, in get
    dest = CallForwardingRecords.objects.all().filter(destination__icontains=query).values()
           ^^^^^^^^^^^^^^^^^^^^^^^^^^^^^^^^^^^^^^^^^^^^^^^^^^^^^^^^^^^^^^^^^^^^^^^^
  File "/home/schwerti/Documents/GitHub/SAMJ-CSDC26BB/SAMJ-Django-TBC/env/lib/python3.12/site-packages/django/db/models/query.py", line 1476, in filter
    return self._filter_or_exclude(False, args, kwargs)
           ^^^^^^^^^^^^^^^^^^^^^^^^^^^^^^^^^^^^^^^^^^^^
  File "/home/schwerti/Documents/GitHub/SAMJ-CSDC26BB/SAMJ-Django-TBC/env/lib/python3.12/site-packages/django/db/models/query.py", line 1494, in _filter_or_exclude
    clone._filter_or_exclude_inplace(negate, args, kwargs)
  File "/home/schwerti/Documents/GitHub/SAMJ-CSDC26BB/SAMJ-Django-TBC/env/lib/python3.12/site-packages/django/db/models/query.py", line 1501, in _filter_or_exclude_inplace
    self._query.add_q(Q(*args, **kwargs))
  File "/home/schwerti/Documents/GitHub/SAMJ-CSDC26BB/SAMJ-Django-TBC/env/lib/python3.12/site-packages/django/db/models/sql/query.py", line 1613, in add_q
    clause, _ = self._add_q(q_object, self.used_aliases)
                ^^^^^^^^^^^^^^^^^^^^^^^^^^^^^^^^^^^^^^^^
  File "/home/schwerti/Documents/GitHub/SAMJ-CSDC26BB/SAMJ-Django-TBC/env/lib/python3.12/site-packages/django/db/models/sql/query.py", line 1645, in _add_q
    child_clause, needed_inner = self.build_filter(
                                 ^^^^^^^^^^^^^^^^^^
  File "/home/schwerti/Documents/GitHub/SAMJ-CSDC26BB/SAMJ-Django-TBC/env/lib/python3.12/site-packages/django/db/models/sql/query.py", line 1559, in build_filter
    condition = self.build_lookup(lookups, col, value)
                ^^^^^^^^^^^^^^^^^^^^^^^^^^^^^^^^^^^^^^
  File "/home/schwerti/Documents/GitHub/SAMJ-CSDC26BB/SAMJ-Django-TBC/env/lib/python3.12/site-packages/django/db/models/sql/query.py", line 1383, in build_lookup
    lhs = self.try_transform(lhs, lookup_name)
          ^^^^^^^^^^^^^^^^^^^^^^^^^^^^^^^^^^^^
  File "/home/schwerti/Documents/GitHub/SAMJ-CSDC26BB/SAMJ-Django-TBC/env/lib/python3.12/site-packages/django/db/models/sql/query.py", line 1427, in try_transform
    raise FieldError(
django.core.exceptions.FieldError: Unsupported lookup 'icontains' for ForeignKey or join on the field not permitted.
[2024-06-17 17:00:43][ERROR] "GET /restEndpoint/?number\=+4367763106443 HTTP/1.1" 500 126717
[2024-06-17 17:00:50][ERROR] Internal Server Error: /restEndpoint/
Traceback (most recent call last):
  File "/home/schwerti/Documents/GitHub/SAMJ-CSDC26BB/SAMJ-Django-TBC/env/lib/python3.12/site-packages/django/core/handlers/exception.py", line 55, in inner
    response = get_response(request)
               ^^^^^^^^^^^^^^^^^^^^^
  File "/home/schwerti/Documents/GitHub/SAMJ-CSDC26BB/SAMJ-Django-TBC/env/lib/python3.12/site-packages/django/core/handlers/base.py", line 197, in _get_response
    response = wrapped_callback(request, *callback_args, **callback_kwargs)
               ^^^^^^^^^^^^^^^^^^^^^^^^^^^^^^^^^^^^^^^^^^^^^^^^^^^^^^^^^^^^
  File "/home/schwerti/Documents/GitHub/SAMJ-CSDC26BB/SAMJ-Django-TBC/env/lib/python3.12/site-packages/django/views/generic/base.py", line 104, in view
    return self.dispatch(request, *args, **kwargs)
           ^^^^^^^^^^^^^^^^^^^^^^^^^^^^^^^^^^^^^^^
  File "/home/schwerti/Documents/GitHub/SAMJ-CSDC26BB/SAMJ-Django-TBC/env/lib/python3.12/site-packages/django/views/generic/base.py", line 143, in dispatch
    return handler(request, *args, **kwargs)
           ^^^^^^^^^^^^^^^^^^^^^^^^^^^^^^^^^
  File "/home/schwerti/Documents/GitHub/SAMJ-CSDC26BB/SAMJ-Django-TBC/samjTBC/samj/viewClasses/restEndpoint.py", line 12, in get
    dest = CallForwardingRecords.objects.all().filter(destination__icontains=query).values()
           ^^^^^^^^^^^^^^^^^^^^^^^^^^^^^^^^^^^^^^^^^^^^^^^^^^^^^^^^^^^^^^^^^^^^^^^^
  File "/home/schwerti/Documents/GitHub/SAMJ-CSDC26BB/SAMJ-Django-TBC/env/lib/python3.12/site-packages/django/db/models/query.py", line 1476, in filter
    return self._filter_or_exclude(False, args, kwargs)
           ^^^^^^^^^^^^^^^^^^^^^^^^^^^^^^^^^^^^^^^^^^^^
  File "/home/schwerti/Documents/GitHub/SAMJ-CSDC26BB/SAMJ-Django-TBC/env/lib/python3.12/site-packages/django/db/models/query.py", line 1494, in _filter_or_exclude
    clone._filter_or_exclude_inplace(negate, args, kwargs)
  File "/home/schwerti/Documents/GitHub/SAMJ-CSDC26BB/SAMJ-Django-TBC/env/lib/python3.12/site-packages/django/db/models/query.py", line 1501, in _filter_or_exclude_inplace
    self._query.add_q(Q(*args, **kwargs))
  File "/home/schwerti/Documents/GitHub/SAMJ-CSDC26BB/SAMJ-Django-TBC/env/lib/python3.12/site-packages/django/db/models/sql/query.py", line 1613, in add_q
    clause, _ = self._add_q(q_object, self.used_aliases)
                ^^^^^^^^^^^^^^^^^^^^^^^^^^^^^^^^^^^^^^^^
  File "/home/schwerti/Documents/GitHub/SAMJ-CSDC26BB/SAMJ-Django-TBC/env/lib/python3.12/site-packages/django/db/models/sql/query.py", line 1645, in _add_q
    child_clause, needed_inner = self.build_filter(
                                 ^^^^^^^^^^^^^^^^^^
  File "/home/schwerti/Documents/GitHub/SAMJ-CSDC26BB/SAMJ-Django-TBC/env/lib/python3.12/site-packages/django/db/models/sql/query.py", line 1559, in build_filter
    condition = self.build_lookup(lookups, col, value)
                ^^^^^^^^^^^^^^^^^^^^^^^^^^^^^^^^^^^^^^
  File "/home/schwerti/Documents/GitHub/SAMJ-CSDC26BB/SAMJ-Django-TBC/env/lib/python3.12/site-packages/django/db/models/sql/query.py", line 1383, in build_lookup
    lhs = self.try_transform(lhs, lookup_name)
          ^^^^^^^^^^^^^^^^^^^^^^^^^^^^^^^^^^^^
  File "/home/schwerti/Documents/GitHub/SAMJ-CSDC26BB/SAMJ-Django-TBC/env/lib/python3.12/site-packages/django/db/models/sql/query.py", line 1427, in try_transform
    raise FieldError(
django.core.exceptions.FieldError: Unsupported lookup 'icontains' for ForeignKey or join on the field not permitted.
[2024-06-17 17:00:50][ERROR] "GET /restEndpoint/?number\=+4367763106443 HTTP/1.1" 500 126717
[2024-06-17 17:00:58][ERROR] Internal Server Error: /restEndpoint/
Traceback (most recent call last):
  File "/home/schwerti/Documents/GitHub/SAMJ-CSDC26BB/SAMJ-Django-TBC/env/lib/python3.12/site-packages/django/core/handlers/exception.py", line 55, in inner
    response = get_response(request)
               ^^^^^^^^^^^^^^^^^^^^^
  File "/home/schwerti/Documents/GitHub/SAMJ-CSDC26BB/SAMJ-Django-TBC/env/lib/python3.12/site-packages/django/core/handlers/base.py", line 197, in _get_response
    response = wrapped_callback(request, *callback_args, **callback_kwargs)
               ^^^^^^^^^^^^^^^^^^^^^^^^^^^^^^^^^^^^^^^^^^^^^^^^^^^^^^^^^^^^
  File "/home/schwerti/Documents/GitHub/SAMJ-CSDC26BB/SAMJ-Django-TBC/env/lib/python3.12/site-packages/django/views/generic/base.py", line 104, in view
    return self.dispatch(request, *args, **kwargs)
           ^^^^^^^^^^^^^^^^^^^^^^^^^^^^^^^^^^^^^^^
  File "/home/schwerti/Documents/GitHub/SAMJ-CSDC26BB/SAMJ-Django-TBC/env/lib/python3.12/site-packages/django/views/generic/base.py", line 143, in dispatch
    return handler(request, *args, **kwargs)
           ^^^^^^^^^^^^^^^^^^^^^^^^^^^^^^^^^
  File "/home/schwerti/Documents/GitHub/SAMJ-CSDC26BB/SAMJ-Django-TBC/samjTBC/samj/viewClasses/restEndpoint.py", line 12, in get
    dest = CallForwardingRecords.objects.all().filter(destination__icontains=query).values()
           ^^^^^^^^^^^^^^^^^^^^^^^^^^^^^^^^^^^^^^^^^^^^^^^^^^^^^^^^^^^^^^^^^^^^^^^^
  File "/home/schwerti/Documents/GitHub/SAMJ-CSDC26BB/SAMJ-Django-TBC/env/lib/python3.12/site-packages/django/db/models/query.py", line 1476, in filter
    return self._filter_or_exclude(False, args, kwargs)
           ^^^^^^^^^^^^^^^^^^^^^^^^^^^^^^^^^^^^^^^^^^^^
  File "/home/schwerti/Documents/GitHub/SAMJ-CSDC26BB/SAMJ-Django-TBC/env/lib/python3.12/site-packages/django/db/models/query.py", line 1494, in _filter_or_exclude
    clone._filter_or_exclude_inplace(negate, args, kwargs)
  File "/home/schwerti/Documents/GitHub/SAMJ-CSDC26BB/SAMJ-Django-TBC/env/lib/python3.12/site-packages/django/db/models/query.py", line 1501, in _filter_or_exclude_inplace
    self._query.add_q(Q(*args, **kwargs))
  File "/home/schwerti/Documents/GitHub/SAMJ-CSDC26BB/SAMJ-Django-TBC/env/lib/python3.12/site-packages/django/db/models/sql/query.py", line 1613, in add_q
    clause, _ = self._add_q(q_object, self.used_aliases)
                ^^^^^^^^^^^^^^^^^^^^^^^^^^^^^^^^^^^^^^^^
  File "/home/schwerti/Documents/GitHub/SAMJ-CSDC26BB/SAMJ-Django-TBC/env/lib/python3.12/site-packages/django/db/models/sql/query.py", line 1645, in _add_q
    child_clause, needed_inner = self.build_filter(
                                 ^^^^^^^^^^^^^^^^^^
  File "/home/schwerti/Documents/GitHub/SAMJ-CSDC26BB/SAMJ-Django-TBC/env/lib/python3.12/site-packages/django/db/models/sql/query.py", line 1559, in build_filter
    condition = self.build_lookup(lookups, col, value)
                ^^^^^^^^^^^^^^^^^^^^^^^^^^^^^^^^^^^^^^
  File "/home/schwerti/Documents/GitHub/SAMJ-CSDC26BB/SAMJ-Django-TBC/env/lib/python3.12/site-packages/django/db/models/sql/query.py", line 1383, in build_lookup
    lhs = self.try_transform(lhs, lookup_name)
          ^^^^^^^^^^^^^^^^^^^^^^^^^^^^^^^^^^^^
  File "/home/schwerti/Documents/GitHub/SAMJ-CSDC26BB/SAMJ-Django-TBC/env/lib/python3.12/site-packages/django/db/models/sql/query.py", line 1427, in try_transform
    raise FieldError(
django.core.exceptions.FieldError: Unsupported lookup 'icontains' for ForeignKey or join on the field not permitted.
[2024-06-17 17:00:58][ERROR] "GET /restEndpoint/?number=+4367763106443 HTTP/1.1" 500 129365
[2024-06-17 17:00:59][WARNING] Not Found: /favicon.ico
[2024-06-17 17:01:11][ERROR] Internal Server Error: /restEndpoint/
Traceback (most recent call last):
  File "/home/schwerti/Documents/GitHub/SAMJ-CSDC26BB/SAMJ-Django-TBC/env/lib/python3.12/site-packages/django/core/handlers/exception.py", line 55, in inner
    response = get_response(request)
               ^^^^^^^^^^^^^^^^^^^^^
  File "/home/schwerti/Documents/GitHub/SAMJ-CSDC26BB/SAMJ-Django-TBC/env/lib/python3.12/site-packages/django/core/handlers/base.py", line 197, in _get_response
    response = wrapped_callback(request, *callback_args, **callback_kwargs)
               ^^^^^^^^^^^^^^^^^^^^^^^^^^^^^^^^^^^^^^^^^^^^^^^^^^^^^^^^^^^^
  File "/home/schwerti/Documents/GitHub/SAMJ-CSDC26BB/SAMJ-Django-TBC/env/lib/python3.12/site-packages/django/views/generic/base.py", line 104, in view
    return self.dispatch(request, *args, **kwargs)
           ^^^^^^^^^^^^^^^^^^^^^^^^^^^^^^^^^^^^^^^
  File "/home/schwerti/Documents/GitHub/SAMJ-CSDC26BB/SAMJ-Django-TBC/env/lib/python3.12/site-packages/django/views/generic/base.py", line 143, in dispatch
    return handler(request, *args, **kwargs)
           ^^^^^^^^^^^^^^^^^^^^^^^^^^^^^^^^^
  File "/home/schwerti/Documents/GitHub/SAMJ-CSDC26BB/SAMJ-Django-TBC/samjTBC/samj/viewClasses/restEndpoint.py", line 12, in get
    dest = CallForwardingRecords.objects.all().filter(destination__icontains=query).values()
           ^^^^^^^^^^^^^^^^^^^^^^^^^^^^^^^^^^^^^^^^^^^^^^^^^^^^^^^^^^^^^^^^^^^^^^^^
  File "/home/schwerti/Documents/GitHub/SAMJ-CSDC26BB/SAMJ-Django-TBC/env/lib/python3.12/site-packages/django/db/models/query.py", line 1476, in filter
    return self._filter_or_exclude(False, args, kwargs)
           ^^^^^^^^^^^^^^^^^^^^^^^^^^^^^^^^^^^^^^^^^^^^
  File "/home/schwerti/Documents/GitHub/SAMJ-CSDC26BB/SAMJ-Django-TBC/env/lib/python3.12/site-packages/django/db/models/query.py", line 1494, in _filter_or_exclude
    clone._filter_or_exclude_inplace(negate, args, kwargs)
  File "/home/schwerti/Documents/GitHub/SAMJ-CSDC26BB/SAMJ-Django-TBC/env/lib/python3.12/site-packages/django/db/models/query.py", line 1501, in _filter_or_exclude_inplace
    self._query.add_q(Q(*args, **kwargs))
  File "/home/schwerti/Documents/GitHub/SAMJ-CSDC26BB/SAMJ-Django-TBC/env/lib/python3.12/site-packages/django/db/models/sql/query.py", line 1613, in add_q
    clause, _ = self._add_q(q_object, self.used_aliases)
                ^^^^^^^^^^^^^^^^^^^^^^^^^^^^^^^^^^^^^^^^
  File "/home/schwerti/Documents/GitHub/SAMJ-CSDC26BB/SAMJ-Django-TBC/env/lib/python3.12/site-packages/django/db/models/sql/query.py", line 1645, in _add_q
    child_clause, needed_inner = self.build_filter(
                                 ^^^^^^^^^^^^^^^^^^
  File "/home/schwerti/Documents/GitHub/SAMJ-CSDC26BB/SAMJ-Django-TBC/env/lib/python3.12/site-packages/django/db/models/sql/query.py", line 1559, in build_filter
    condition = self.build_lookup(lookups, col, value)
                ^^^^^^^^^^^^^^^^^^^^^^^^^^^^^^^^^^^^^^
  File "/home/schwerti/Documents/GitHub/SAMJ-CSDC26BB/SAMJ-Django-TBC/env/lib/python3.12/site-packages/django/db/models/sql/query.py", line 1383, in build_lookup
    lhs = self.try_transform(lhs, lookup_name)
          ^^^^^^^^^^^^^^^^^^^^^^^^^^^^^^^^^^^^
  File "/home/schwerti/Documents/GitHub/SAMJ-CSDC26BB/SAMJ-Django-TBC/env/lib/python3.12/site-packages/django/db/models/sql/query.py", line 1427, in try_transform
    raise FieldError(
django.core.exceptions.FieldError: Unsupported lookup 'icontains' for ForeignKey or join on the field not permitted.
[2024-06-17 17:01:11][ERROR] "GET /restEndpoint/?number=%27+4367763106443%27 HTTP/1.1" 500 129545
[2024-06-17 17:02:16][ERROR] Internal Server Error: /restEndpoint/
Traceback (most recent call last):
  File "/home/schwerti/Documents/GitHub/SAMJ-CSDC26BB/SAMJ-Django-TBC/env/lib/python3.12/site-packages/django/core/handlers/exception.py", line 55, in inner
    response = get_response(request)
               ^^^^^^^^^^^^^^^^^^^^^
  File "/home/schwerti/Documents/GitHub/SAMJ-CSDC26BB/SAMJ-Django-TBC/env/lib/python3.12/site-packages/django/core/handlers/base.py", line 197, in _get_response
    response = wrapped_callback(request, *callback_args, **callback_kwargs)
               ^^^^^^^^^^^^^^^^^^^^^^^^^^^^^^^^^^^^^^^^^^^^^^^^^^^^^^^^^^^^
  File "/home/schwerti/Documents/GitHub/SAMJ-CSDC26BB/SAMJ-Django-TBC/env/lib/python3.12/site-packages/django/views/generic/base.py", line 104, in view
    return self.dispatch(request, *args, **kwargs)
           ^^^^^^^^^^^^^^^^^^^^^^^^^^^^^^^^^^^^^^^
  File "/home/schwerti/Documents/GitHub/SAMJ-CSDC26BB/SAMJ-Django-TBC/env/lib/python3.12/site-packages/django/views/generic/base.py", line 143, in dispatch
    return handler(request, *args, **kwargs)
           ^^^^^^^^^^^^^^^^^^^^^^^^^^^^^^^^^
  File "/home/schwerti/Documents/GitHub/SAMJ-CSDC26BB/SAMJ-Django-TBC/samjTBC/samj/viewClasses/restEndpoint.py", line 12, in get
    dest = CallForwardingRecords.objects.all().filter(destination__icontains=query).values()
           ^^^^^^^^^^^^^^^^^^^^^^^^^^^^^^^^^^^^^^^^^^^^^^^^^^^^^^^^^^^^^^^^^^^^^^^^
  File "/home/schwerti/Documents/GitHub/SAMJ-CSDC26BB/SAMJ-Django-TBC/env/lib/python3.12/site-packages/django/db/models/query.py", line 1476, in filter
    return self._filter_or_exclude(False, args, kwargs)
           ^^^^^^^^^^^^^^^^^^^^^^^^^^^^^^^^^^^^^^^^^^^^
  File "/home/schwerti/Documents/GitHub/SAMJ-CSDC26BB/SAMJ-Django-TBC/env/lib/python3.12/site-packages/django/db/models/query.py", line 1494, in _filter_or_exclude
    clone._filter_or_exclude_inplace(negate, args, kwargs)
  File "/home/schwerti/Documents/GitHub/SAMJ-CSDC26BB/SAMJ-Django-TBC/env/lib/python3.12/site-packages/django/db/models/query.py", line 1501, in _filter_or_exclude_inplace
    self._query.add_q(Q(*args, **kwargs))
  File "/home/schwerti/Documents/GitHub/SAMJ-CSDC26BB/SAMJ-Django-TBC/env/lib/python3.12/site-packages/django/db/models/sql/query.py", line 1613, in add_q
    clause, _ = self._add_q(q_object, self.used_aliases)
                ^^^^^^^^^^^^^^^^^^^^^^^^^^^^^^^^^^^^^^^^
  File "/home/schwerti/Documents/GitHub/SAMJ-CSDC26BB/SAMJ-Django-TBC/env/lib/python3.12/site-packages/django/db/models/sql/query.py", line 1645, in _add_q
    child_clause, needed_inner = self.build_filter(
                                 ^^^^^^^^^^^^^^^^^^
  File "/home/schwerti/Documents/GitHub/SAMJ-CSDC26BB/SAMJ-Django-TBC/env/lib/python3.12/site-packages/django/db/models/sql/query.py", line 1559, in build_filter
    condition = self.build_lookup(lookups, col, value)
                ^^^^^^^^^^^^^^^^^^^^^^^^^^^^^^^^^^^^^^
  File "/home/schwerti/Documents/GitHub/SAMJ-CSDC26BB/SAMJ-Django-TBC/env/lib/python3.12/site-packages/django/db/models/sql/query.py", line 1383, in build_lookup
    lhs = self.try_transform(lhs, lookup_name)
          ^^^^^^^^^^^^^^^^^^^^^^^^^^^^^^^^^^^^
  File "/home/schwerti/Documents/GitHub/SAMJ-CSDC26BB/SAMJ-Django-TBC/env/lib/python3.12/site-packages/django/db/models/sql/query.py", line 1427, in try_transform
    raise FieldError(
django.core.exceptions.FieldError: Unsupported lookup 'icontains' for ForeignKey or join on the field not permitted.
[2024-06-17 17:02:16][ERROR] "GET /restEndpoint/?number=+4367763106443 HTTP/1.1" 500 129365
[2024-06-17 17:03:07][ERROR] Internal Server Error: /restEndpoint/
Traceback (most recent call last):
  File "/home/schwerti/Documents/GitHub/SAMJ-CSDC26BB/SAMJ-Django-TBC/env/lib/python3.12/site-packages/django/core/handlers/exception.py", line 55, in inner
    response = get_response(request)
               ^^^^^^^^^^^^^^^^^^^^^
  File "/home/schwerti/Documents/GitHub/SAMJ-CSDC26BB/SAMJ-Django-TBC/env/lib/python3.12/site-packages/django/core/handlers/base.py", line 197, in _get_response
    response = wrapped_callback(request, *callback_args, **callback_kwargs)
               ^^^^^^^^^^^^^^^^^^^^^^^^^^^^^^^^^^^^^^^^^^^^^^^^^^^^^^^^^^^^
  File "/home/schwerti/Documents/GitHub/SAMJ-CSDC26BB/SAMJ-Django-TBC/env/lib/python3.12/site-packages/django/views/generic/base.py", line 104, in view
    return self.dispatch(request, *args, **kwargs)
           ^^^^^^^^^^^^^^^^^^^^^^^^^^^^^^^^^^^^^^^
  File "/home/schwerti/Documents/GitHub/SAMJ-CSDC26BB/SAMJ-Django-TBC/env/lib/python3.12/site-packages/django/views/generic/base.py", line 143, in dispatch
    return handler(request, *args, **kwargs)
           ^^^^^^^^^^^^^^^^^^^^^^^^^^^^^^^^^
  File "/home/schwerti/Documents/GitHub/SAMJ-CSDC26BB/SAMJ-Django-TBC/samjTBC/samj/viewClasses/restEndpoint.py", line 12, in get
    dest = CallForwardingRecords.objects.all().filter(destination__icontains=query).values()
           ^^^^^^^^^^^^^^^^^^^^^^^^^^^^^^^^^^^^^^^^^^^^^^^^^^^^^^^^^^^^^^^^^^^^^^^^
  File "/home/schwerti/Documents/GitHub/SAMJ-CSDC26BB/SAMJ-Django-TBC/env/lib/python3.12/site-packages/django/db/models/query.py", line 1476, in filter
    return self._filter_or_exclude(False, args, kwargs)
           ^^^^^^^^^^^^^^^^^^^^^^^^^^^^^^^^^^^^^^^^^^^^
  File "/home/schwerti/Documents/GitHub/SAMJ-CSDC26BB/SAMJ-Django-TBC/env/lib/python3.12/site-packages/django/db/models/query.py", line 1494, in _filter_or_exclude
    clone._filter_or_exclude_inplace(negate, args, kwargs)
  File "/home/schwerti/Documents/GitHub/SAMJ-CSDC26BB/SAMJ-Django-TBC/env/lib/python3.12/site-packages/django/db/models/query.py", line 1501, in _filter_or_exclude_inplace
    self._query.add_q(Q(*args, **kwargs))
  File "/home/schwerti/Documents/GitHub/SAMJ-CSDC26BB/SAMJ-Django-TBC/env/lib/python3.12/site-packages/django/db/models/sql/query.py", line 1613, in add_q
    clause, _ = self._add_q(q_object, self.used_aliases)
                ^^^^^^^^^^^^^^^^^^^^^^^^^^^^^^^^^^^^^^^^
  File "/home/schwerti/Documents/GitHub/SAMJ-CSDC26BB/SAMJ-Django-TBC/env/lib/python3.12/site-packages/django/db/models/sql/query.py", line 1645, in _add_q
    child_clause, needed_inner = self.build_filter(
                                 ^^^^^^^^^^^^^^^^^^
  File "/home/schwerti/Documents/GitHub/SAMJ-CSDC26BB/SAMJ-Django-TBC/env/lib/python3.12/site-packages/django/db/models/sql/query.py", line 1559, in build_filter
    condition = self.build_lookup(lookups, col, value)
                ^^^^^^^^^^^^^^^^^^^^^^^^^^^^^^^^^^^^^^
  File "/home/schwerti/Documents/GitHub/SAMJ-CSDC26BB/SAMJ-Django-TBC/env/lib/python3.12/site-packages/django/db/models/sql/query.py", line 1383, in build_lookup
    lhs = self.try_transform(lhs, lookup_name)
          ^^^^^^^^^^^^^^^^^^^^^^^^^^^^^^^^^^^^
  File "/home/schwerti/Documents/GitHub/SAMJ-CSDC26BB/SAMJ-Django-TBC/env/lib/python3.12/site-packages/django/db/models/sql/query.py", line 1427, in try_transform
    raise FieldError(
django.core.exceptions.FieldError: Unsupported lookup 'icontains' for ForeignKey or join on the field not permitted.
[2024-06-17 17:03:07][ERROR] "GET /restEndpoint/?number=\+4367763106443 HTTP/1.1" 500 129410
[2024-06-17 17:04:55][ERROR] Internal Server Error: /restEndpoint/
Traceback (most recent call last):
  File "/home/schwerti/Documents/GitHub/SAMJ-CSDC26BB/SAMJ-Django-TBC/env/lib/python3.12/site-packages/django/core/handlers/exception.py", line 55, in inner
    response = get_response(request)
               ^^^^^^^^^^^^^^^^^^^^^
  File "/home/schwerti/Documents/GitHub/SAMJ-CSDC26BB/SAMJ-Django-TBC/env/lib/python3.12/site-packages/django/core/handlers/base.py", line 197, in _get_response
    response = wrapped_callback(request, *callback_args, **callback_kwargs)
               ^^^^^^^^^^^^^^^^^^^^^^^^^^^^^^^^^^^^^^^^^^^^^^^^^^^^^^^^^^^^
  File "/home/schwerti/Documents/GitHub/SAMJ-CSDC26BB/SAMJ-Django-TBC/env/lib/python3.12/site-packages/django/views/generic/base.py", line 104, in view
    return self.dispatch(request, *args, **kwargs)
           ^^^^^^^^^^^^^^^^^^^^^^^^^^^^^^^^^^^^^^^
  File "/home/schwerti/Documents/GitHub/SAMJ-CSDC26BB/SAMJ-Django-TBC/env/lib/python3.12/site-packages/django/views/generic/base.py", line 143, in dispatch
    return handler(request, *args, **kwargs)
           ^^^^^^^^^^^^^^^^^^^^^^^^^^^^^^^^^
  File "/home/schwerti/Documents/GitHub/SAMJ-CSDC26BB/SAMJ-Django-TBC/samjTBC/samj/viewClasses/restEndpoint.py", line 12, in get
    dest = CallForwardingRecords.objects.all().filter(destination__icontains=query).values()
           ^^^^^^^^^^^^^^^^^^^^^^^^^^^^^^^^^^^^^^^^^^^^^^^^^^^^^^^^^^^^^^^^^^^^^^^^
  File "/home/schwerti/Documents/GitHub/SAMJ-CSDC26BB/SAMJ-Django-TBC/env/lib/python3.12/site-packages/django/db/models/query.py", line 1476, in filter
    return self._filter_or_exclude(False, args, kwargs)
           ^^^^^^^^^^^^^^^^^^^^^^^^^^^^^^^^^^^^^^^^^^^^
  File "/home/schwerti/Documents/GitHub/SAMJ-CSDC26BB/SAMJ-Django-TBC/env/lib/python3.12/site-packages/django/db/models/query.py", line 1494, in _filter_or_exclude
    clone._filter_or_exclude_inplace(negate, args, kwargs)
  File "/home/schwerti/Documents/GitHub/SAMJ-CSDC26BB/SAMJ-Django-TBC/env/lib/python3.12/site-packages/django/db/models/query.py", line 1501, in _filter_or_exclude_inplace
    self._query.add_q(Q(*args, **kwargs))
  File "/home/schwerti/Documents/GitHub/SAMJ-CSDC26BB/SAMJ-Django-TBC/env/lib/python3.12/site-packages/django/db/models/sql/query.py", line 1613, in add_q
    clause, _ = self._add_q(q_object, self.used_aliases)
                ^^^^^^^^^^^^^^^^^^^^^^^^^^^^^^^^^^^^^^^^
  File "/home/schwerti/Documents/GitHub/SAMJ-CSDC26BB/SAMJ-Django-TBC/env/lib/python3.12/site-packages/django/db/models/sql/query.py", line 1645, in _add_q
    child_clause, needed_inner = self.build_filter(
                                 ^^^^^^^^^^^^^^^^^^
  File "/home/schwerti/Documents/GitHub/SAMJ-CSDC26BB/SAMJ-Django-TBC/env/lib/python3.12/site-packages/django/db/models/sql/query.py", line 1559, in build_filter
    condition = self.build_lookup(lookups, col, value)
                ^^^^^^^^^^^^^^^^^^^^^^^^^^^^^^^^^^^^^^
  File "/home/schwerti/Documents/GitHub/SAMJ-CSDC26BB/SAMJ-Django-TBC/env/lib/python3.12/site-packages/django/db/models/sql/query.py", line 1383, in build_lookup
    lhs = self.try_transform(lhs, lookup_name)
          ^^^^^^^^^^^^^^^^^^^^^^^^^^^^^^^^^^^^
  File "/home/schwerti/Documents/GitHub/SAMJ-CSDC26BB/SAMJ-Django-TBC/env/lib/python3.12/site-packages/django/db/models/sql/query.py", line 1427, in try_transform
    raise FieldError(
django.core.exceptions.FieldError: Unsupported lookup 'icontains' for ForeignKey or join on the field not permitted.
[2024-06-17 17:04:55][ERROR] "GET /restEndpoint/?number=%2B4367763106443 HTTP/1.1" 500 129381
[2024-06-17 17:05:20][WARNING] Not Found: /favicon.ico
[2024-06-17 17:06:53][ERROR] Internal Server Error: /restEndpoint/
Traceback (most recent call last):
  File "/home/schwerti/Documents/GitHub/SAMJ-CSDC26BB/SAMJ-Django-TBC/env/lib/python3.12/site-packages/django/core/handlers/exception.py", line 55, in inner
    response = get_response(request)
               ^^^^^^^^^^^^^^^^^^^^^
  File "/home/schwerti/Documents/GitHub/SAMJ-CSDC26BB/SAMJ-Django-TBC/env/lib/python3.12/site-packages/django/core/handlers/base.py", line 197, in _get_response
    response = wrapped_callback(request, *callback_args, **callback_kwargs)
               ^^^^^^^^^^^^^^^^^^^^^^^^^^^^^^^^^^^^^^^^^^^^^^^^^^^^^^^^^^^^
  File "/home/schwerti/Documents/GitHub/SAMJ-CSDC26BB/SAMJ-Django-TBC/env/lib/python3.12/site-packages/django/views/generic/base.py", line 104, in view
    return self.dispatch(request, *args, **kwargs)
           ^^^^^^^^^^^^^^^^^^^^^^^^^^^^^^^^^^^^^^^
  File "/home/schwerti/Documents/GitHub/SAMJ-CSDC26BB/SAMJ-Django-TBC/env/lib/python3.12/site-packages/django/views/generic/base.py", line 143, in dispatch
    return handler(request, *args, **kwargs)
           ^^^^^^^^^^^^^^^^^^^^^^^^^^^^^^^^^
  File "/home/schwerti/Documents/GitHub/SAMJ-CSDC26BB/SAMJ-Django-TBC/samjTBC/samj/viewClasses/restEndpoint.py", line 13, in get
    logger.info(dest[0]["destination_id"])
                ~~~~^^^
  File "/home/schwerti/Documents/GitHub/SAMJ-CSDC26BB/SAMJ-Django-TBC/env/lib/python3.12/site-packages/django/db/models/query.py", line 452, in __getitem__
    return qs._result_cache[0]
           ~~~~~~~~~~~~~~~~^^^
IndexError: list index out of range
[2024-06-17 17:06:53][ERROR] "GET /restEndpoint/?number=%2B4367763106443 HTTP/1.1" 500 89740
[2024-06-17 17:06:53][WARNING] Not Found: /favicon.ico
[2024-06-17 17:07:44][WARNING] Not Found: /favicon.ico
[2024-06-17 17:08:17][WARNING] Not Found: /favicon.ico
[2024-06-17 17:08:29][WARNING] Not Found: /favicon.ico
[2024-06-17 17:08:57][WARNING] Not Found: /favicon.ico
[2024-06-17 17:08:59][WARNING] Not Found: /favicon.ico
[2024-06-17 17:09:30][ERROR] Internal Server Error: /restEndpoint/
Traceback (most recent call last):
  File "/home/schwerti/Documents/GitHub/SAMJ-CSDC26BB/SAMJ-Django-TBC/env/lib/python3.12/site-packages/django/core/handlers/exception.py", line 55, in inner
    response = get_response(request)
               ^^^^^^^^^^^^^^^^^^^^^
  File "/home/schwerti/Documents/GitHub/SAMJ-CSDC26BB/SAMJ-Django-TBC/env/lib/python3.12/site-packages/django/core/handlers/base.py", line 197, in _get_response
    response = wrapped_callback(request, *callback_args, **callback_kwargs)
               ^^^^^^^^^^^^^^^^^^^^^^^^^^^^^^^^^^^^^^^^^^^^^^^^^^^^^^^^^^^^
  File "/home/schwerti/Documents/GitHub/SAMJ-CSDC26BB/SAMJ-Django-TBC/env/lib/python3.12/site-packages/django/views/generic/base.py", line 104, in view
    return self.dispatch(request, *args, **kwargs)
           ^^^^^^^^^^^^^^^^^^^^^^^^^^^^^^^^^^^^^^^
  File "/home/schwerti/Documents/GitHub/SAMJ-CSDC26BB/SAMJ-Django-TBC/env/lib/python3.12/site-packages/django/views/generic/base.py", line 143, in dispatch
    return handler(request, *args, **kwargs)
           ^^^^^^^^^^^^^^^^^^^^^^^^^^^^^^^^^
  File "/home/schwerti/Documents/GitHub/SAMJ-CSDC26BB/SAMJ-Django-TBC/samjTBC/samj/viewClasses/restEndpoint.py", line 13, in get
    logger.info(dest[0]["destination_id"])
                ~~~~^^^
  File "/home/schwerti/Documents/GitHub/SAMJ-CSDC26BB/SAMJ-Django-TBC/env/lib/python3.12/site-packages/django/db/models/query.py", line 452, in __getitem__
    return qs._result_cache[0]
           ~~~~~~~~~~~~~~~~^^^
IndexError: list index out of range
[2024-06-17 17:09:30][ERROR] "GET /restEndpoint/?number=%2B4367763106443 HTTP/1.1" 500 89747
[2024-06-17 17:10:13][WARNING] Not Found: /favicon.ico
[2024-06-17 17:10:31][ERROR] Internal Server Error: /restEndpoint/
Traceback (most recent call last):
  File "/home/schwerti/Documents/GitHub/SAMJ-CSDC26BB/SAMJ-Django-TBC/env/lib/python3.12/site-packages/django/core/handlers/exception.py", line 55, in inner
    response = get_response(request)
               ^^^^^^^^^^^^^^^^^^^^^
  File "/home/schwerti/Documents/GitHub/SAMJ-CSDC26BB/SAMJ-Django-TBC/env/lib/python3.12/site-packages/django/core/handlers/base.py", line 197, in _get_response
    response = wrapped_callback(request, *callback_args, **callback_kwargs)
               ^^^^^^^^^^^^^^^^^^^^^^^^^^^^^^^^^^^^^^^^^^^^^^^^^^^^^^^^^^^^
  File "/home/schwerti/Documents/GitHub/SAMJ-CSDC26BB/SAMJ-Django-TBC/env/lib/python3.12/site-packages/django/views/generic/base.py", line 104, in view
    return self.dispatch(request, *args, **kwargs)
           ^^^^^^^^^^^^^^^^^^^^^^^^^^^^^^^^^^^^^^^
  File "/home/schwerti/Documents/GitHub/SAMJ-CSDC26BB/SAMJ-Django-TBC/env/lib/python3.12/site-packages/django/views/generic/base.py", line 143, in dispatch
    return handler(request, *args, **kwargs)
           ^^^^^^^^^^^^^^^^^^^^^^^^^^^^^^^^^
  File "/home/schwerti/Documents/GitHub/SAMJ-CSDC26BB/SAMJ-Django-TBC/samjTBC/samj/viewClasses/restEndpoint.py", line 12, in get
    logger.info("objects -> " + CallForwardingRecords.objects.all())
                ~~~~~~~~~~~~~~^~~~~~~~~~~~~~~~~~~~~~~~~~~~~~~~~~~~~
TypeError: can only concatenate str (not "QuerySet") to str
[2024-06-17 17:10:31][ERROR] "GET /restEndpoint/?number=%2B4367763106443 HTTP/1.1" 500 86107
[2024-06-17 17:10:32][WARNING] Not Found: /favicon.ico
[2024-06-17 17:11:03][ERROR] Internal Server Error: /restEndpoint/
Traceback (most recent call last):
  File "/home/schwerti/Documents/GitHub/SAMJ-CSDC26BB/SAMJ-Django-TBC/env/lib/python3.12/site-packages/django/core/handlers/exception.py", line 55, in inner
    response = get_response(request)
               ^^^^^^^^^^^^^^^^^^^^^
  File "/home/schwerti/Documents/GitHub/SAMJ-CSDC26BB/SAMJ-Django-TBC/env/lib/python3.12/site-packages/django/core/handlers/base.py", line 197, in _get_response
    response = wrapped_callback(request, *callback_args, **callback_kwargs)
               ^^^^^^^^^^^^^^^^^^^^^^^^^^^^^^^^^^^^^^^^^^^^^^^^^^^^^^^^^^^^
  File "/home/schwerti/Documents/GitHub/SAMJ-CSDC26BB/SAMJ-Django-TBC/env/lib/python3.12/site-packages/django/views/generic/base.py", line 104, in view
    return self.dispatch(request, *args, **kwargs)
           ^^^^^^^^^^^^^^^^^^^^^^^^^^^^^^^^^^^^^^^
  File "/home/schwerti/Documents/GitHub/SAMJ-CSDC26BB/SAMJ-Django-TBC/env/lib/python3.12/site-packages/django/views/generic/base.py", line 143, in dispatch
    return handler(request, *args, **kwargs)
           ^^^^^^^^^^^^^^^^^^^^^^^^^^^^^^^^^
  File "/home/schwerti/Documents/GitHub/SAMJ-CSDC26BB/SAMJ-Django-TBC/samjTBC/samj/viewClasses/restEndpoint.py", line 13, in get
    dest = CallForwardingRecords.objects.all().filter(destination_id__icontains=query).values()
           ^^^^^^^^^^^^^^^^^^^^^^^^^^^^^^^^^^^^^^^^^^^^^^^^^^^^^^^^^^^^^^^^^^^^^^^^^^^
  File "/home/schwerti/Documents/GitHub/SAMJ-CSDC26BB/SAMJ-Django-TBC/env/lib/python3.12/site-packages/django/db/models/query.py", line 1476, in filter
    return self._filter_or_exclude(False, args, kwargs)
           ^^^^^^^^^^^^^^^^^^^^^^^^^^^^^^^^^^^^^^^^^^^^
  File "/home/schwerti/Documents/GitHub/SAMJ-CSDC26BB/SAMJ-Django-TBC/env/lib/python3.12/site-packages/django/db/models/query.py", line 1494, in _filter_or_exclude
    clone._filter_or_exclude_inplace(negate, args, kwargs)
  File "/home/schwerti/Documents/GitHub/SAMJ-CSDC26BB/SAMJ-Django-TBC/env/lib/python3.12/site-packages/django/db/models/query.py", line 1501, in _filter_or_exclude_inplace
    self._query.add_q(Q(*args, **kwargs))
  File "/home/schwerti/Documents/GitHub/SAMJ-CSDC26BB/SAMJ-Django-TBC/env/lib/python3.12/site-packages/django/db/models/sql/query.py", line 1613, in add_q
    clause, _ = self._add_q(q_object, self.used_aliases)
                ^^^^^^^^^^^^^^^^^^^^^^^^^^^^^^^^^^^^^^^^
  File "/home/schwerti/Documents/GitHub/SAMJ-CSDC26BB/SAMJ-Django-TBC/env/lib/python3.12/site-packages/django/db/models/sql/query.py", line 1645, in _add_q
    child_clause, needed_inner = self.build_filter(
                                 ^^^^^^^^^^^^^^^^^^
  File "/home/schwerti/Documents/GitHub/SAMJ-CSDC26BB/SAMJ-Django-TBC/env/lib/python3.12/site-packages/django/db/models/sql/query.py", line 1559, in build_filter
    condition = self.build_lookup(lookups, col, value)
                ^^^^^^^^^^^^^^^^^^^^^^^^^^^^^^^^^^^^^^
  File "/home/schwerti/Documents/GitHub/SAMJ-CSDC26BB/SAMJ-Django-TBC/env/lib/python3.12/site-packages/django/db/models/sql/query.py", line 1383, in build_lookup
    lhs = self.try_transform(lhs, lookup_name)
          ^^^^^^^^^^^^^^^^^^^^^^^^^^^^^^^^^^^^
  File "/home/schwerti/Documents/GitHub/SAMJ-CSDC26BB/SAMJ-Django-TBC/env/lib/python3.12/site-packages/django/db/models/sql/query.py", line 1427, in try_transform
    raise FieldError(
django.core.exceptions.FieldError: Unsupported lookup 'icontains' for ForeignKey or join on the field not permitted.
[2024-06-17 17:11:03][ERROR] "GET /restEndpoint/?number=%2B4367763106443 HTTP/1.1" 500 129506
[2024-06-17 17:11:04][WARNING] Not Found: /favicon.ico
[2024-06-17 17:15:29][ERROR] Internal Server Error: /restEndpoint/
Traceback (most recent call last):
  File "/home/schwerti/Documents/GitHub/SAMJ-CSDC26BB/SAMJ-Django-TBC/env/lib/python3.12/site-packages/django/core/handlers/exception.py", line 55, in inner
    response = get_response(request)
               ^^^^^^^^^^^^^^^^^^^^^
  File "/home/schwerti/Documents/GitHub/SAMJ-CSDC26BB/SAMJ-Django-TBC/env/lib/python3.12/site-packages/django/core/handlers/base.py", line 197, in _get_response
    response = wrapped_callback(request, *callback_args, **callback_kwargs)
               ^^^^^^^^^^^^^^^^^^^^^^^^^^^^^^^^^^^^^^^^^^^^^^^^^^^^^^^^^^^^
  File "/home/schwerti/Documents/GitHub/SAMJ-CSDC26BB/SAMJ-Django-TBC/env/lib/python3.12/site-packages/django/views/generic/base.py", line 104, in view
    return self.dispatch(request, *args, **kwargs)
           ^^^^^^^^^^^^^^^^^^^^^^^^^^^^^^^^^^^^^^^
  File "/home/schwerti/Documents/GitHub/SAMJ-CSDC26BB/SAMJ-Django-TBC/env/lib/python3.12/site-packages/django/views/generic/base.py", line 143, in dispatch
    return handler(request, *args, **kwargs)
           ^^^^^^^^^^^^^^^^^^^^^^^^^^^^^^^^^
  File "/home/schwerti/Documents/GitHub/SAMJ-CSDC26BB/SAMJ-Django-TBC/samjTBC/samj/viewClasses/restEndpoint.py", line 14, in get
    logger.info(dest[0])
                ~~~~^^^
  File "/home/schwerti/Documents/GitHub/SAMJ-CSDC26BB/SAMJ-Django-TBC/env/lib/python3.12/site-packages/django/db/models/query.py", line 452, in __getitem__
    return qs._result_cache[0]
           ~~~~~~~~~~~~~~~~^^^
IndexError: list index out of range
[2024-06-17 17:15:29][ERROR] "GET /restEndpoint/?number=%2B4367763106443 HTTP/1.1" 500 89752
[2024-06-17 17:15:29][WARNING] Not Found: /favicon.ico
[2024-06-17 17:15:59][ERROR] Internal Server Error: /restEndpoint/
Traceback (most recent call last):
  File "/home/schwerti/Documents/GitHub/SAMJ-CSDC26BB/SAMJ-Django-TBC/env/lib/python3.12/site-packages/django/core/handlers/exception.py", line 55, in inner
    response = get_response(request)
               ^^^^^^^^^^^^^^^^^^^^^
  File "/home/schwerti/Documents/GitHub/SAMJ-CSDC26BB/SAMJ-Django-TBC/env/lib/python3.12/site-packages/django/core/handlers/base.py", line 197, in _get_response
    response = wrapped_callback(request, *callback_args, **callback_kwargs)
               ^^^^^^^^^^^^^^^^^^^^^^^^^^^^^^^^^^^^^^^^^^^^^^^^^^^^^^^^^^^^
  File "/home/schwerti/Documents/GitHub/SAMJ-CSDC26BB/SAMJ-Django-TBC/env/lib/python3.12/site-packages/django/views/generic/base.py", line 104, in view
    return self.dispatch(request, *args, **kwargs)
           ^^^^^^^^^^^^^^^^^^^^^^^^^^^^^^^^^^^^^^^
  File "/home/schwerti/Documents/GitHub/SAMJ-CSDC26BB/SAMJ-Django-TBC/env/lib/python3.12/site-packages/django/views/generic/base.py", line 143, in dispatch
    return handler(request, *args, **kwargs)
           ^^^^^^^^^^^^^^^^^^^^^^^^^^^^^^^^^
  File "/home/schwerti/Documents/GitHub/SAMJ-CSDC26BB/SAMJ-Django-TBC/samjTBC/samj/viewClasses/restEndpoint.py", line 14, in get
    logger.info("info: " + dest[0])
                           ~~~~^^^
  File "/home/schwerti/Documents/GitHub/SAMJ-CSDC26BB/SAMJ-Django-TBC/env/lib/python3.12/site-packages/django/db/models/query.py", line 452, in __getitem__
    return qs._result_cache[0]
           ~~~~~~~~~~~~~~~~^^^
IndexError: list index out of range
[2024-06-17 17:15:59][ERROR] "GET /restEndpoint/?number=%2B4367763106443 HTTP/1.1" 500 89816
[2024-06-17 17:15:59][WARNING] Not Found: /favicon.ico
[2024-06-17 17:16:03][ERROR] Internal Server Error: /restEndpoint/
Traceback (most recent call last):
  File "/home/schwerti/Documents/GitHub/SAMJ-CSDC26BB/SAMJ-Django-TBC/env/lib/python3.12/site-packages/django/core/handlers/exception.py", line 55, in inner
    response = get_response(request)
               ^^^^^^^^^^^^^^^^^^^^^
  File "/home/schwerti/Documents/GitHub/SAMJ-CSDC26BB/SAMJ-Django-TBC/env/lib/python3.12/site-packages/django/core/handlers/base.py", line 197, in _get_response
    response = wrapped_callback(request, *callback_args, **callback_kwargs)
               ^^^^^^^^^^^^^^^^^^^^^^^^^^^^^^^^^^^^^^^^^^^^^^^^^^^^^^^^^^^^
  File "/home/schwerti/Documents/GitHub/SAMJ-CSDC26BB/SAMJ-Django-TBC/env/lib/python3.12/site-packages/django/views/generic/base.py", line 104, in view
    return self.dispatch(request, *args, **kwargs)
           ^^^^^^^^^^^^^^^^^^^^^^^^^^^^^^^^^^^^^^^
  File "/home/schwerti/Documents/GitHub/SAMJ-CSDC26BB/SAMJ-Django-TBC/env/lib/python3.12/site-packages/django/views/generic/base.py", line 143, in dispatch
    return handler(request, *args, **kwargs)
           ^^^^^^^^^^^^^^^^^^^^^^^^^^^^^^^^^
  File "/home/schwerti/Documents/GitHub/SAMJ-CSDC26BB/SAMJ-Django-TBC/samjTBC/samj/viewClasses/restEndpoint.py", line 14, in get
    logger.info("info: " + dest[0])
                           ~~~~^^^
  File "/home/schwerti/Documents/GitHub/SAMJ-CSDC26BB/SAMJ-Django-TBC/env/lib/python3.12/site-packages/django/db/models/query.py", line 452, in __getitem__
    return qs._result_cache[0]
           ~~~~~~~~~~~~~~~~^^^
IndexError: list index out of range
[2024-06-17 17:16:03][ERROR] "GET /restEndpoint/?number=%2B4367763106443 HTTP/1.1" 500 89816
[2024-06-17 17:16:03][WARNING] Not Found: /favicon.ico
[2024-06-17 17:16:27][ERROR] Internal Server Error: /restEndpoint/
Traceback (most recent call last):
  File "/home/schwerti/Documents/GitHub/SAMJ-CSDC26BB/SAMJ-Django-TBC/env/lib/python3.12/site-packages/django/core/handlers/exception.py", line 55, in inner
    response = get_response(request)
               ^^^^^^^^^^^^^^^^^^^^^
  File "/home/schwerti/Documents/GitHub/SAMJ-CSDC26BB/SAMJ-Django-TBC/env/lib/python3.12/site-packages/django/core/handlers/base.py", line 197, in _get_response
    response = wrapped_callback(request, *callback_args, **callback_kwargs)
               ^^^^^^^^^^^^^^^^^^^^^^^^^^^^^^^^^^^^^^^^^^^^^^^^^^^^^^^^^^^^
  File "/home/schwerti/Documents/GitHub/SAMJ-CSDC26BB/SAMJ-Django-TBC/env/lib/python3.12/site-packages/django/views/generic/base.py", line 104, in view
    return self.dispatch(request, *args, **kwargs)
           ^^^^^^^^^^^^^^^^^^^^^^^^^^^^^^^^^^^^^^^
  File "/home/schwerti/Documents/GitHub/SAMJ-CSDC26BB/SAMJ-Django-TBC/env/lib/python3.12/site-packages/django/views/generic/base.py", line 143, in dispatch
    return handler(request, *args, **kwargs)
           ^^^^^^^^^^^^^^^^^^^^^^^^^^^^^^^^^
  File "/home/schwerti/Documents/GitHub/SAMJ-CSDC26BB/SAMJ-Django-TBC/samjTBC/samj/viewClasses/restEndpoint.py", line 14, in get
    logger.info("info: " + dest[0])
                ~~~~~~~~~^~~~~~~~~
TypeError: can only concatenate str (not "dict") to str
[2024-06-17 17:16:27][ERROR] "GET /restEndpoint/?number=%2B4367763106443 HTTP/1.1" 500 86123
[2024-06-17 17:16:40][ERROR] Internal Server Error: /restEndpoint/
Traceback (most recent call last):
  File "/home/schwerti/Documents/GitHub/SAMJ-CSDC26BB/SAMJ-Django-TBC/env/lib/python3.12/site-packages/django/core/handlers/exception.py", line 55, in inner
    response = get_response(request)
               ^^^^^^^^^^^^^^^^^^^^^
  File "/home/schwerti/Documents/GitHub/SAMJ-CSDC26BB/SAMJ-Django-TBC/env/lib/python3.12/site-packages/django/core/handlers/base.py", line 197, in _get_response
    response = wrapped_callback(request, *callback_args, **callback_kwargs)
               ^^^^^^^^^^^^^^^^^^^^^^^^^^^^^^^^^^^^^^^^^^^^^^^^^^^^^^^^^^^^
  File "/home/schwerti/Documents/GitHub/SAMJ-CSDC26BB/SAMJ-Django-TBC/env/lib/python3.12/site-packages/django/views/generic/base.py", line 104, in view
    return self.dispatch(request, *args, **kwargs)
           ^^^^^^^^^^^^^^^^^^^^^^^^^^^^^^^^^^^^^^^
  File "/home/schwerti/Documents/GitHub/SAMJ-CSDC26BB/SAMJ-Django-TBC/env/lib/python3.12/site-packages/django/views/generic/base.py", line 143, in dispatch
    return handler(request, *args, **kwargs)
           ^^^^^^^^^^^^^^^^^^^^^^^^^^^^^^^^^
  File "/home/schwerti/Documents/GitHub/SAMJ-CSDC26BB/SAMJ-Django-TBC/samjTBC/samj/viewClasses/restEndpoint.py", line 14, in get
    logger.info("info: " + dest)
                ~~~~~~~~~^~~~~~
TypeError: can only concatenate str (not "QuerySet") to str
[2024-06-17 17:16:40][ERROR] "GET /restEndpoint/?number=%2B4367763106443 HTTP/1.1" 500 86127
[2024-06-17 17:16:40][WARNING] Not Found: /favicon.ico
[2024-06-17 17:17:32][ERROR] Internal Server Error: /restEndpoint/
Traceback (most recent call last):
  File "/home/schwerti/Documents/GitHub/SAMJ-CSDC26BB/SAMJ-Django-TBC/env/lib/python3.12/site-packages/django/core/handlers/exception.py", line 55, in inner
    response = get_response(request)
               ^^^^^^^^^^^^^^^^^^^^^
  File "/home/schwerti/Documents/GitHub/SAMJ-CSDC26BB/SAMJ-Django-TBC/env/lib/python3.12/site-packages/django/core/handlers/base.py", line 197, in _get_response
    response = wrapped_callback(request, *callback_args, **callback_kwargs)
               ^^^^^^^^^^^^^^^^^^^^^^^^^^^^^^^^^^^^^^^^^^^^^^^^^^^^^^^^^^^^
  File "/home/schwerti/Documents/GitHub/SAMJ-CSDC26BB/SAMJ-Django-TBC/env/lib/python3.12/site-packages/django/views/generic/base.py", line 104, in view
    return self.dispatch(request, *args, **kwargs)
           ^^^^^^^^^^^^^^^^^^^^^^^^^^^^^^^^^^^^^^^
  File "/home/schwerti/Documents/GitHub/SAMJ-CSDC26BB/SAMJ-Django-TBC/env/lib/python3.12/site-packages/django/views/generic/base.py", line 143, in dispatch
    return handler(request, *args, **kwargs)
           ^^^^^^^^^^^^^^^^^^^^^^^^^^^^^^^^^
  File "/home/schwerti/Documents/GitHub/SAMJ-CSDC26BB/SAMJ-Django-TBC/samjTBC/samj/viewClasses/restEndpoint.py", line 11, in get
    dest = CallForwardingRecords.objects.all().filter(destination__icontains=query).values()
           ^^^^^^^^^^^^^^^^^^^^^^^^^^^^^^^^^^^^^^^^^^^^^^^^^^^^^^^^^^^^^^^^^^^^^^^^
  File "/home/schwerti/Documents/GitHub/SAMJ-CSDC26BB/SAMJ-Django-TBC/env/lib/python3.12/site-packages/django/db/models/query.py", line 1476, in filter
    return self._filter_or_exclude(False, args, kwargs)
           ^^^^^^^^^^^^^^^^^^^^^^^^^^^^^^^^^^^^^^^^^^^^
  File "/home/schwerti/Documents/GitHub/SAMJ-CSDC26BB/SAMJ-Django-TBC/env/lib/python3.12/site-packages/django/db/models/query.py", line 1494, in _filter_or_exclude
    clone._filter_or_exclude_inplace(negate, args, kwargs)
  File "/home/schwerti/Documents/GitHub/SAMJ-CSDC26BB/SAMJ-Django-TBC/env/lib/python3.12/site-packages/django/db/models/query.py", line 1501, in _filter_or_exclude_inplace
    self._query.add_q(Q(*args, **kwargs))
  File "/home/schwerti/Documents/GitHub/SAMJ-CSDC26BB/SAMJ-Django-TBC/env/lib/python3.12/site-packages/django/db/models/sql/query.py", line 1613, in add_q
    clause, _ = self._add_q(q_object, self.used_aliases)
                ^^^^^^^^^^^^^^^^^^^^^^^^^^^^^^^^^^^^^^^^
  File "/home/schwerti/Documents/GitHub/SAMJ-CSDC26BB/SAMJ-Django-TBC/env/lib/python3.12/site-packages/django/db/models/sql/query.py", line 1645, in _add_q
    child_clause, needed_inner = self.build_filter(
                                 ^^^^^^^^^^^^^^^^^^
  File "/home/schwerti/Documents/GitHub/SAMJ-CSDC26BB/SAMJ-Django-TBC/env/lib/python3.12/site-packages/django/db/models/sql/query.py", line 1559, in build_filter
    condition = self.build_lookup(lookups, col, value)
                ^^^^^^^^^^^^^^^^^^^^^^^^^^^^^^^^^^^^^^
  File "/home/schwerti/Documents/GitHub/SAMJ-CSDC26BB/SAMJ-Django-TBC/env/lib/python3.12/site-packages/django/db/models/sql/query.py", line 1383, in build_lookup
    lhs = self.try_transform(lhs, lookup_name)
          ^^^^^^^^^^^^^^^^^^^^^^^^^^^^^^^^^^^^
  File "/home/schwerti/Documents/GitHub/SAMJ-CSDC26BB/SAMJ-Django-TBC/env/lib/python3.12/site-packages/django/db/models/sql/query.py", line 1427, in try_transform
    raise FieldError(
django.core.exceptions.FieldError: Unsupported lookup 'icontains' for ForeignKey or join on the field not permitted.
[2024-06-17 17:17:32][ERROR] "GET /restEndpoint/?number=%2B4367763106443 HTTP/1.1" 500 129246
[2024-06-17 17:17:33][WARNING] Not Found: /favicon.ico
[2024-06-17 17:17:50][ERROR] Internal Server Error: /restEndpoint/
Traceback (most recent call last):
  File "/home/schwerti/Documents/GitHub/SAMJ-CSDC26BB/SAMJ-Django-TBC/env/lib/python3.12/site-packages/django/core/handlers/exception.py", line 55, in inner
    response = get_response(request)
               ^^^^^^^^^^^^^^^^^^^^^
  File "/home/schwerti/Documents/GitHub/SAMJ-CSDC26BB/SAMJ-Django-TBC/env/lib/python3.12/site-packages/django/core/handlers/base.py", line 197, in _get_response
    response = wrapped_callback(request, *callback_args, **callback_kwargs)
               ^^^^^^^^^^^^^^^^^^^^^^^^^^^^^^^^^^^^^^^^^^^^^^^^^^^^^^^^^^^^
  File "/home/schwerti/Documents/GitHub/SAMJ-CSDC26BB/SAMJ-Django-TBC/env/lib/python3.12/site-packages/django/views/generic/base.py", line 104, in view
    return self.dispatch(request, *args, **kwargs)
           ^^^^^^^^^^^^^^^^^^^^^^^^^^^^^^^^^^^^^^^
  File "/home/schwerti/Documents/GitHub/SAMJ-CSDC26BB/SAMJ-Django-TBC/env/lib/python3.12/site-packages/django/views/generic/base.py", line 143, in dispatch
    return handler(request, *args, **kwargs)
           ^^^^^^^^^^^^^^^^^^^^^^^^^^^^^^^^^
  File "/home/schwerti/Documents/GitHub/SAMJ-CSDC26BB/SAMJ-Django-TBC/samjTBC/samj/viewClasses/restEndpoint.py", line 11, in get
    dest = CallForwardingRecords.objects.all().filter(source_number=query)
           ^^^^^^^^^^^^^^^^^^^^^^^^^^^^^^^^^^^^^^^^^^^^^^^^^^^^^^^^^^^^^^^
  File "/home/schwerti/Documents/GitHub/SAMJ-CSDC26BB/SAMJ-Django-TBC/env/lib/python3.12/site-packages/django/db/models/query.py", line 1476, in filter
    return self._filter_or_exclude(False, args, kwargs)
           ^^^^^^^^^^^^^^^^^^^^^^^^^^^^^^^^^^^^^^^^^^^^
  File "/home/schwerti/Documents/GitHub/SAMJ-CSDC26BB/SAMJ-Django-TBC/env/lib/python3.12/site-packages/django/db/models/query.py", line 1494, in _filter_or_exclude
    clone._filter_or_exclude_inplace(negate, args, kwargs)
  File "/home/schwerti/Documents/GitHub/SAMJ-CSDC26BB/SAMJ-Django-TBC/env/lib/python3.12/site-packages/django/db/models/query.py", line 1501, in _filter_or_exclude_inplace
    self._query.add_q(Q(*args, **kwargs))
  File "/home/schwerti/Documents/GitHub/SAMJ-CSDC26BB/SAMJ-Django-TBC/env/lib/python3.12/site-packages/django/db/models/sql/query.py", line 1613, in add_q
    clause, _ = self._add_q(q_object, self.used_aliases)
                ^^^^^^^^^^^^^^^^^^^^^^^^^^^^^^^^^^^^^^^^
  File "/home/schwerti/Documents/GitHub/SAMJ-CSDC26BB/SAMJ-Django-TBC/env/lib/python3.12/site-packages/django/db/models/sql/query.py", line 1645, in _add_q
    child_clause, needed_inner = self.build_filter(
                                 ^^^^^^^^^^^^^^^^^^
  File "/home/schwerti/Documents/GitHub/SAMJ-CSDC26BB/SAMJ-Django-TBC/env/lib/python3.12/site-packages/django/db/models/sql/query.py", line 1495, in build_filter
    lookups, parts, reffed_expression = self.solve_lookup_type(arg, summarize)
                                        ^^^^^^^^^^^^^^^^^^^^^^^^^^^^^^^^^^^^^^
  File "/home/schwerti/Documents/GitHub/SAMJ-CSDC26BB/SAMJ-Django-TBC/env/lib/python3.12/site-packages/django/db/models/sql/query.py", line 1307, in solve_lookup_type
    _, field, _, lookup_parts = self.names_to_path(lookup_splitted, self.get_meta())
                                ^^^^^^^^^^^^^^^^^^^^^^^^^^^^^^^^^^^^^^^^^^^^^^^^^^^^
  File "/home/schwerti/Documents/GitHub/SAMJ-CSDC26BB/SAMJ-Django-TBC/env/lib/python3.12/site-packages/django/db/models/sql/query.py", line 1772, in names_to_path
    raise FieldError(
django.core.exceptions.FieldError: Cannot resolve keyword 'source_number' into field. Choices are: calledNumber, destination, destination_id, endDate, id, startDate, username
[2024-06-17 17:17:50][ERROR] "GET /restEndpoint/?number=%2B4367763106443 HTTP/1.1" 500 127327
[2024-06-17 17:17:50][WARNING] Not Found: /favicon.ico
[2024-06-17 17:19:30][ERROR] Internal Server Error: /restEndpoint/
Traceback (most recent call last):
  File "/home/schwerti/Documents/GitHub/SAMJ-CSDC26BB/SAMJ-Django-TBC/env/lib/python3.12/site-packages/django/core/handlers/exception.py", line 55, in inner
    response = get_response(request)
               ^^^^^^^^^^^^^^^^^^^^^
  File "/home/schwerti/Documents/GitHub/SAMJ-CSDC26BB/SAMJ-Django-TBC/env/lib/python3.12/site-packages/django/core/handlers/base.py", line 197, in _get_response
    response = wrapped_callback(request, *callback_args, **callback_kwargs)
               ^^^^^^^^^^^^^^^^^^^^^^^^^^^^^^^^^^^^^^^^^^^^^^^^^^^^^^^^^^^^
  File "/home/schwerti/Documents/GitHub/SAMJ-CSDC26BB/SAMJ-Django-TBC/env/lib/python3.12/site-packages/django/views/generic/base.py", line 104, in view
    return self.dispatch(request, *args, **kwargs)
           ^^^^^^^^^^^^^^^^^^^^^^^^^^^^^^^^^^^^^^^
  File "/home/schwerti/Documents/GitHub/SAMJ-CSDC26BB/SAMJ-Django-TBC/env/lib/python3.12/site-packages/django/views/generic/base.py", line 143, in dispatch
    return handler(request, *args, **kwargs)
           ^^^^^^^^^^^^^^^^^^^^^^^^^^^^^^^^^
  File "/home/schwerti/Documents/GitHub/SAMJ-CSDC26BB/SAMJ-Django-TBC/samjTBC/samj/viewClasses/restEndpoint.py", line 12, in get
    logger.info(dest[0]["destination_id"])
                ~~~~~~~^^^^^^^^^^^^^^^^^^
TypeError: 'CallForwardingRecords' object is not subscriptable
[2024-06-17 17:19:30][ERROR] "GET /restEndpoint/?number\=%2B4367763106443 HTTP/1.1" 500 83230
[2024-06-17 17:20:28][WARNING] Not Found: /favicon.ico
[2024-06-17 17:21:57][WARNING] Not Found: /favicon.ico
[2024-06-17 17:22:03][WARNING] Not Found: /favicon.ico
[2024-06-17 17:24:10][ERROR] Internal Server Error: /restEndpoint/
Traceback (most recent call last):
  File "/home/schwerti/Documents/GitHub/SAMJ-CSDC26BB/SAMJ-Django-TBC/env/lib/python3.12/site-packages/django/core/handlers/exception.py", line 55, in inner
    response = get_response(request)
               ^^^^^^^^^^^^^^^^^^^^^
  File "/home/schwerti/Documents/GitHub/SAMJ-CSDC26BB/SAMJ-Django-TBC/env/lib/python3.12/site-packages/django/core/handlers/base.py", line 197, in _get_response
    response = wrapped_callback(request, *callback_args, **callback_kwargs)
               ^^^^^^^^^^^^^^^^^^^^^^^^^^^^^^^^^^^^^^^^^^^^^^^^^^^^^^^^^^^^
  File "/home/schwerti/Documents/GitHub/SAMJ-CSDC26BB/SAMJ-Django-TBC/env/lib/python3.12/site-packages/django/views/generic/base.py", line 104, in view
    return self.dispatch(request, *args, **kwargs)
           ^^^^^^^^^^^^^^^^^^^^^^^^^^^^^^^^^^^^^^^
  File "/home/schwerti/Documents/GitHub/SAMJ-CSDC26BB/SAMJ-Django-TBC/env/lib/python3.12/site-packages/django/views/generic/base.py", line 143, in dispatch
    return handler(request, *args, **kwargs)
           ^^^^^^^^^^^^^^^^^^^^^^^^^^^^^^^^^
  File "/home/schwerti/Documents/GitHub/SAMJ-CSDC26BB/SAMJ-Django-TBC/samjTBC/samj/viewClasses/restEndpoint.py", line 12, in get
    dest = CallForwardingRecords.objects.all().values().filter(calledNumber=query)["destination_id"]
           ~~~~~~~~~~~~~~~~~~~~~~~~~~~~~~~~~~~~~~~~~~~~~~~~~~~~~~~~~~~~~~~~~~~~~~~^^^^^^^^^^^^^^^^^^
  File "/home/schwerti/Documents/GitHub/SAMJ-CSDC26BB/SAMJ-Django-TBC/env/lib/python3.12/site-packages/django/db/models/query.py", line 420, in __getitem__
    raise TypeError(
TypeError: QuerySet indices must be integers or slices, not str.
[2024-06-17 17:24:10][ERROR] "GET /restEndpoint/?number=%2B4367763106443 HTTP/1.1" 500 89988
[2024-06-17 17:24:11][WARNING] Not Found: /favicon.ico
[2024-06-17 17:24:22][ERROR] Internal Server Error: /restEndpoint/
Traceback (most recent call last):
  File "/home/schwerti/Documents/GitHub/SAMJ-CSDC26BB/SAMJ-Django-TBC/env/lib/python3.12/site-packages/django/core/handlers/exception.py", line 55, in inner
    response = get_response(request)
               ^^^^^^^^^^^^^^^^^^^^^
  File "/home/schwerti/Documents/GitHub/SAMJ-CSDC26BB/SAMJ-Django-TBC/env/lib/python3.12/site-packages/django/core/handlers/base.py", line 197, in _get_response
    response = wrapped_callback(request, *callback_args, **callback_kwargs)
               ^^^^^^^^^^^^^^^^^^^^^^^^^^^^^^^^^^^^^^^^^^^^^^^^^^^^^^^^^^^^
  File "/home/schwerti/Documents/GitHub/SAMJ-CSDC26BB/SAMJ-Django-TBC/env/lib/python3.12/site-packages/django/views/generic/base.py", line 104, in view
    return self.dispatch(request, *args, **kwargs)
           ^^^^^^^^^^^^^^^^^^^^^^^^^^^^^^^^^^^^^^^
  File "/home/schwerti/Documents/GitHub/SAMJ-CSDC26BB/SAMJ-Django-TBC/env/lib/python3.12/site-packages/django/views/generic/base.py", line 143, in dispatch
    return handler(request, *args, **kwargs)
           ^^^^^^^^^^^^^^^^^^^^^^^^^^^^^^^^^
  File "/home/schwerti/Documents/GitHub/SAMJ-CSDC26BB/SAMJ-Django-TBC/samjTBC/samj/viewClasses/restEndpoint.py", line 12, in get
    dest = CallForwardingRecords.objects.all().values().filter(calledNumber=query)["destination_id"]
           ~~~~~~~~~~~~~~~~~~~~~~~~~~~~~~~~~~~~~~~~~~~~~~~~~~~~~~~~~~~~~~~~~~~~~~~^^^^^^^^^^^^^^^^^^
  File "/home/schwerti/Documents/GitHub/SAMJ-CSDC26BB/SAMJ-Django-TBC/env/lib/python3.12/site-packages/django/db/models/query.py", line 420, in __getitem__
    raise TypeError(
TypeError: QuerySet indices must be integers or slices, not str.
[2024-06-17 17:24:22][ERROR] "GET /restEndpoint/?number=%2B4367763106443 HTTP/1.1" 500 89999
[2024-06-17 17:24:22][WARNING] Not Found: /favicon.ico
[2024-06-17 17:24:44][WARNING] Not Found: /favicon.ico
[2024-06-17 17:27:57][WARNING] Not Found: /favicon.ico
[2024-06-17 17:28:05][ERROR] Internal Server Error: /restEndpoint/
Traceback (most recent call last):
  File "/home/schwerti/Documents/GitHub/SAMJ-CSDC26BB/SAMJ-Django-TBC/env/lib/python3.12/site-packages/django/core/handlers/exception.py", line 55, in inner
    response = get_response(request)
               ^^^^^^^^^^^^^^^^^^^^^
  File "/home/schwerti/Documents/GitHub/SAMJ-CSDC26BB/SAMJ-Django-TBC/env/lib/python3.12/site-packages/django/core/handlers/base.py", line 197, in _get_response
    response = wrapped_callback(request, *callback_args, **callback_kwargs)
               ^^^^^^^^^^^^^^^^^^^^^^^^^^^^^^^^^^^^^^^^^^^^^^^^^^^^^^^^^^^^
  File "/home/schwerti/Documents/GitHub/SAMJ-CSDC26BB/SAMJ-Django-TBC/env/lib/python3.12/site-packages/django/views/generic/base.py", line 104, in view
    return self.dispatch(request, *args, **kwargs)
           ^^^^^^^^^^^^^^^^^^^^^^^^^^^^^^^^^^^^^^^
  File "/home/schwerti/Documents/GitHub/SAMJ-CSDC26BB/SAMJ-Django-TBC/env/lib/python3.12/site-packages/django/views/generic/base.py", line 143, in dispatch
    return handler(request, *args, **kwargs)
           ^^^^^^^^^^^^^^^^^^^^^^^^^^^^^^^^^
  File "/home/schwerti/Documents/GitHub/SAMJ-CSDC26BB/SAMJ-Django-TBC/samjTBC/samj/viewClasses/restEndpoint.py", line 15, in get
    logger.info(dest["destination_id"])
                ~~~~^^^^^^^^^^^^^^^^^^
TypeError: string indices must be integers, not 'str'
[2024-06-17 17:28:05][ERROR] "GET /restEndpoint/?number\=%2B4367763106443 HTTP/1.1" 500 83217
[2024-06-17 17:28:15][WARNING] Not Found: /favicon.ico
[2024-06-17 17:28:28][ERROR] Internal Server Error: /restEndpoint/
Traceback (most recent call last):
  File "/home/schwerti/Documents/GitHub/SAMJ-CSDC26BB/SAMJ-Django-TBC/env/lib/python3.12/site-packages/django/core/handlers/exception.py", line 55, in inner
    response = get_response(request)
               ^^^^^^^^^^^^^^^^^^^^^
  File "/home/schwerti/Documents/GitHub/SAMJ-CSDC26BB/SAMJ-Django-TBC/env/lib/python3.12/site-packages/django/core/handlers/base.py", line 197, in _get_response
    response = wrapped_callback(request, *callback_args, **callback_kwargs)
               ^^^^^^^^^^^^^^^^^^^^^^^^^^^^^^^^^^^^^^^^^^^^^^^^^^^^^^^^^^^^
  File "/home/schwerti/Documents/GitHub/SAMJ-CSDC26BB/SAMJ-Django-TBC/env/lib/python3.12/site-packages/django/views/generic/base.py", line 104, in view
    return self.dispatch(request, *args, **kwargs)
           ^^^^^^^^^^^^^^^^^^^^^^^^^^^^^^^^^^^^^^^
  File "/home/schwerti/Documents/GitHub/SAMJ-CSDC26BB/SAMJ-Django-TBC/env/lib/python3.12/site-packages/django/views/generic/base.py", line 143, in dispatch
    return handler(request, *args, **kwargs)
           ^^^^^^^^^^^^^^^^^^^^^^^^^^^^^^^^^
  File "/home/schwerti/Documents/GitHub/SAMJ-CSDC26BB/SAMJ-Django-TBC/samjTBC/samj/viewClasses/restEndpoint.py", line 15, in get
    logger.info(dest["destination_id"])
                ~~~~^^^^^^^^^^^^^^^^^^
TypeError: string indices must be integers, not 'str'
[2024-06-17 17:28:28][ERROR] "GET /restEndpoint/?number\=%2B4367763106443 HTTP/1.1" 500 83217
[2024-06-17 17:29:03][ERROR] Internal Server Error: /restEndpoint/
Traceback (most recent call last):
  File "/home/schwerti/Documents/GitHub/SAMJ-CSDC26BB/SAMJ-Django-TBC/env/lib/python3.12/site-packages/django/core/handlers/exception.py", line 55, in inner
    response = get_response(request)
               ^^^^^^^^^^^^^^^^^^^^^
  File "/home/schwerti/Documents/GitHub/SAMJ-CSDC26BB/SAMJ-Django-TBC/env/lib/python3.12/site-packages/django/core/handlers/base.py", line 197, in _get_response
    response = wrapped_callback(request, *callback_args, **callback_kwargs)
               ^^^^^^^^^^^^^^^^^^^^^^^^^^^^^^^^^^^^^^^^^^^^^^^^^^^^^^^^^^^^
  File "/home/schwerti/Documents/GitHub/SAMJ-CSDC26BB/SAMJ-Django-TBC/env/lib/python3.12/site-packages/django/views/generic/base.py", line 104, in view
    return self.dispatch(request, *args, **kwargs)
           ^^^^^^^^^^^^^^^^^^^^^^^^^^^^^^^^^^^^^^^
  File "/home/schwerti/Documents/GitHub/SAMJ-CSDC26BB/SAMJ-Django-TBC/env/lib/python3.12/site-packages/django/views/generic/base.py", line 143, in dispatch
    return handler(request, *args, **kwargs)
           ^^^^^^^^^^^^^^^^^^^^^^^^^^^^^^^^^
  File "/home/schwerti/Documents/GitHub/SAMJ-CSDC26BB/SAMJ-Django-TBC/samjTBC/samj/viewClasses/restEndpoint.py", line 15, in get
    logger.info(dest["destination_id"])
                ~~~~^^^^^^^^^^^^^^^^^^
TypeError: string indices must be integers, not 'str'
[2024-06-17 17:29:03][ERROR] "GET /restEndpoint/?number=%2B436776310644 HTTP/1.1" 500 83197
[2024-06-17 17:29:06][ERROR] Internal Server Error: /restEndpoint/
Traceback (most recent call last):
  File "/home/schwerti/Documents/GitHub/SAMJ-CSDC26BB/SAMJ-Django-TBC/env/lib/python3.12/site-packages/django/core/handlers/exception.py", line 55, in inner
    response = get_response(request)
               ^^^^^^^^^^^^^^^^^^^^^
  File "/home/schwerti/Documents/GitHub/SAMJ-CSDC26BB/SAMJ-Django-TBC/env/lib/python3.12/site-packages/django/core/handlers/base.py", line 197, in _get_response
    response = wrapped_callback(request, *callback_args, **callback_kwargs)
               ^^^^^^^^^^^^^^^^^^^^^^^^^^^^^^^^^^^^^^^^^^^^^^^^^^^^^^^^^^^^
  File "/home/schwerti/Documents/GitHub/SAMJ-CSDC26BB/SAMJ-Django-TBC/env/lib/python3.12/site-packages/django/views/generic/base.py", line 104, in view
    return self.dispatch(request, *args, **kwargs)
           ^^^^^^^^^^^^^^^^^^^^^^^^^^^^^^^^^^^^^^^
  File "/home/schwerti/Documents/GitHub/SAMJ-CSDC26BB/SAMJ-Django-TBC/env/lib/python3.12/site-packages/django/views/generic/base.py", line 143, in dispatch
    return handler(request, *args, **kwargs)
           ^^^^^^^^^^^^^^^^^^^^^^^^^^^^^^^^^
  File "/home/schwerti/Documents/GitHub/SAMJ-CSDC26BB/SAMJ-Django-TBC/samjTBC/samj/viewClasses/restEndpoint.py", line 15, in get
    logger.info(dest["destination_id"])
                ~~~~^^^^^^^^^^^^^^^^^^
TypeError: string indices must be integers, not 'str'
[2024-06-17 17:29:06][ERROR] "GET /restEndpoint/?number=%2B4367763 HTTP/1.1" 500 83147
[2024-06-17 17:29:12][ERROR] Internal Server Error: /restEndpoint/
Traceback (most recent call last):
  File "/home/schwerti/Documents/GitHub/SAMJ-CSDC26BB/SAMJ-Django-TBC/env/lib/python3.12/site-packages/django/core/handlers/exception.py", line 55, in inner
    response = get_response(request)
               ^^^^^^^^^^^^^^^^^^^^^
  File "/home/schwerti/Documents/GitHub/SAMJ-CSDC26BB/SAMJ-Django-TBC/env/lib/python3.12/site-packages/django/core/handlers/base.py", line 197, in _get_response
    response = wrapped_callback(request, *callback_args, **callback_kwargs)
               ^^^^^^^^^^^^^^^^^^^^^^^^^^^^^^^^^^^^^^^^^^^^^^^^^^^^^^^^^^^^
  File "/home/schwerti/Documents/GitHub/SAMJ-CSDC26BB/SAMJ-Django-TBC/env/lib/python3.12/site-packages/django/views/generic/base.py", line 104, in view
    return self.dispatch(request, *args, **kwargs)
           ^^^^^^^^^^^^^^^^^^^^^^^^^^^^^^^^^^^^^^^
  File "/home/schwerti/Documents/GitHub/SAMJ-CSDC26BB/SAMJ-Django-TBC/env/lib/python3.12/site-packages/django/views/generic/base.py", line 143, in dispatch
    return handler(request, *args, **kwargs)
           ^^^^^^^^^^^^^^^^^^^^^^^^^^^^^^^^^
  File "/home/schwerti/Documents/GitHub/SAMJ-CSDC26BB/SAMJ-Django-TBC/samjTBC/samj/viewClasses/restEndpoint.py", line 15, in get
    logger.info(dest["destination_id"])
                ~~~~^^^^^^^^^^^^^^^^^^
TypeError: string indices must be integers, not 'str'
[2024-06-17 17:29:12][ERROR] "GET /restEndpoint/?number=%2B4367763 HTTP/1.1" 500 83147
[2024-06-17 17:29:15][ERROR] Internal Server Error: /restEndpoint/
Traceback (most recent call last):
  File "/home/schwerti/Documents/GitHub/SAMJ-CSDC26BB/SAMJ-Django-TBC/env/lib/python3.12/site-packages/django/core/handlers/exception.py", line 55, in inner
    response = get_response(request)
               ^^^^^^^^^^^^^^^^^^^^^
  File "/home/schwerti/Documents/GitHub/SAMJ-CSDC26BB/SAMJ-Django-TBC/env/lib/python3.12/site-packages/django/core/handlers/base.py", line 197, in _get_response
    response = wrapped_callback(request, *callback_args, **callback_kwargs)
               ^^^^^^^^^^^^^^^^^^^^^^^^^^^^^^^^^^^^^^^^^^^^^^^^^^^^^^^^^^^^
  File "/home/schwerti/Documents/GitHub/SAMJ-CSDC26BB/SAMJ-Django-TBC/env/lib/python3.12/site-packages/django/views/generic/base.py", line 104, in view
    return self.dispatch(request, *args, **kwargs)
           ^^^^^^^^^^^^^^^^^^^^^^^^^^^^^^^^^^^^^^^
  File "/home/schwerti/Documents/GitHub/SAMJ-CSDC26BB/SAMJ-Django-TBC/env/lib/python3.12/site-packages/django/views/generic/base.py", line 143, in dispatch
    return handler(request, *args, **kwargs)
           ^^^^^^^^^^^^^^^^^^^^^^^^^^^^^^^^^
  File "/home/schwerti/Documents/GitHub/SAMJ-CSDC26BB/SAMJ-Django-TBC/samjTBC/samj/viewClasses/restEndpoint.py", line 15, in get
    logger.info(dest["destination_id"])
                ~~~~^^^^^^^^^^^^^^^^^^
TypeError: string indices must be integers, not 'str'
[2024-06-17 17:29:15][ERROR] "GET /restEndpoint/?number=%2B436776310644 HTTP/1.1" 500 83197
[2024-06-17 17:29:19][ERROR] Internal Server Error: /restEndpoint/
Traceback (most recent call last):
  File "/home/schwerti/Documents/GitHub/SAMJ-CSDC26BB/SAMJ-Django-TBC/env/lib/python3.12/site-packages/django/core/handlers/exception.py", line 55, in inner
    response = get_response(request)
               ^^^^^^^^^^^^^^^^^^^^^
  File "/home/schwerti/Documents/GitHub/SAMJ-CSDC26BB/SAMJ-Django-TBC/env/lib/python3.12/site-packages/django/core/handlers/base.py", line 197, in _get_response
    response = wrapped_callback(request, *callback_args, **callback_kwargs)
               ^^^^^^^^^^^^^^^^^^^^^^^^^^^^^^^^^^^^^^^^^^^^^^^^^^^^^^^^^^^^
  File "/home/schwerti/Documents/GitHub/SAMJ-CSDC26BB/SAMJ-Django-TBC/env/lib/python3.12/site-packages/django/views/generic/base.py", line 104, in view
    return self.dispatch(request, *args, **kwargs)
           ^^^^^^^^^^^^^^^^^^^^^^^^^^^^^^^^^^^^^^^
  File "/home/schwerti/Documents/GitHub/SAMJ-CSDC26BB/SAMJ-Django-TBC/env/lib/python3.12/site-packages/django/views/generic/base.py", line 143, in dispatch
    return handler(request, *args, **kwargs)
           ^^^^^^^^^^^^^^^^^^^^^^^^^^^^^^^^^
  File "/home/schwerti/Documents/GitHub/SAMJ-CSDC26BB/SAMJ-Django-TBC/samjTBC/samj/viewClasses/restEndpoint.py", line 15, in get
    logger.info(dest["destination_id"])
                ~~~~^^^^^^^^^^^^^^^^^^
TypeError: string indices must be integers, not 'str'
[2024-06-17 17:29:19][ERROR] "GET /restEndpoint/?number=%2B436776310644 HTTP/1.1" 500 83197
[2024-06-17 17:31:29][ERROR] Internal Server Error: /restEndpoint/
Traceback (most recent call last):
  File "/home/schwerti/Documents/GitHub/SAMJ-CSDC26BB/SAMJ-Django-TBC/env/lib/python3.12/site-packages/django/core/handlers/exception.py", line 55, in inner
    response = get_response(request)
               ^^^^^^^^^^^^^^^^^^^^^
  File "/home/schwerti/Documents/GitHub/SAMJ-CSDC26BB/SAMJ-Django-TBC/env/lib/python3.12/site-packages/django/core/handlers/base.py", line 197, in _get_response
    response = wrapped_callback(request, *callback_args, **callback_kwargs)
               ^^^^^^^^^^^^^^^^^^^^^^^^^^^^^^^^^^^^^^^^^^^^^^^^^^^^^^^^^^^^
  File "/home/schwerti/Documents/GitHub/SAMJ-CSDC26BB/SAMJ-Django-TBC/env/lib/python3.12/site-packages/django/views/generic/base.py", line 104, in view
    return self.dispatch(request, *args, **kwargs)
           ^^^^^^^^^^^^^^^^^^^^^^^^^^^^^^^^^^^^^^^
  File "/home/schwerti/Documents/GitHub/SAMJ-CSDC26BB/SAMJ-Django-TBC/env/lib/python3.12/site-packages/django/views/generic/base.py", line 143, in dispatch
    return handler(request, *args, **kwargs)
           ^^^^^^^^^^^^^^^^^^^^^^^^^^^^^^^^^
  File "/home/schwerti/Documents/GitHub/SAMJ-CSDC26BB/SAMJ-Django-TBC/samjTBC/samj/viewClasses/restEndpoint.py", line 18, in get
    return HttpResponse(dest["destination_id"])
                        ~~~~^^^^^^^^^^^^^^^^^^
TypeError: string indices must be integers, not 'str'
[2024-06-17 17:31:29][ERROR] "GET /restEndpoint/?number=%2B436776310644 HTTP/1.1" 500 82973
[2024-06-17 17:39:56][ERROR] Internal Server Error: /restEndpoint/
Traceback (most recent call last):
  File "/home/schwerti/Documents/GitHub/SAMJ-CSDC26BB/SAMJ-Django-TBC/env/lib/python3.12/site-packages/django/core/handlers/exception.py", line 55, in inner
    response = get_response(request)
               ^^^^^^^^^^^^^^^^^^^^^
  File "/home/schwerti/Documents/GitHub/SAMJ-CSDC26BB/SAMJ-Django-TBC/env/lib/python3.12/site-packages/django/core/handlers/base.py", line 197, in _get_response
    response = wrapped_callback(request, *callback_args, **callback_kwargs)
               ^^^^^^^^^^^^^^^^^^^^^^^^^^^^^^^^^^^^^^^^^^^^^^^^^^^^^^^^^^^^
  File "/home/schwerti/Documents/GitHub/SAMJ-CSDC26BB/SAMJ-Django-TBC/env/lib/python3.12/site-packages/django/views/generic/base.py", line 104, in view
    return self.dispatch(request, *args, **kwargs)
           ^^^^^^^^^^^^^^^^^^^^^^^^^^^^^^^^^^^^^^^
  File "/home/schwerti/Documents/GitHub/SAMJ-CSDC26BB/SAMJ-Django-TBC/env/lib/python3.12/site-packages/django/views/generic/base.py", line 143, in dispatch
    return handler(request, *args, **kwargs)
           ^^^^^^^^^^^^^^^^^^^^^^^^^^^^^^^^^
  File "/home/schwerti/Documents/GitHub/SAMJ-CSDC26BB/SAMJ-Django-TBC/samjTBC/samj/viewClasses/restEndpoint.py", line 11, in get
    dest = getDest(query)
           ^^^^^^^
NameError: name 'getDest' is not defined
[2024-06-17 17:39:56][ERROR] "GET /restEndpoint/?number=%2B4367763106443 HTTP/1.1" 500 85554
[2024-06-17 17:39:56][WARNING] Not Found: /favicon.ico
